Workbook
Name Category_New: 'Time Plan (Lacy))'!$F$5
Name Category_New: 'Time Plan (Multiple Release)'!$F$5
Name Category_New: 'Time Plan (Partial Phani)'!$F$5
Name Category_New: 'Time Plan HY'!$F$5
Name Category_New: 'Time Plan (Single Release)'!$F$5
Name ClientList: INDEX(Table2[Client Name],0)
Name ClientList: INDEX(Table2[Client Name],0)
Name ClientList: INDEX(Table2[Client Name],0)
Name ClientList: INDEX(Table2[Client Name],0)
Name ClientList: INDEX(Table2[Client Name],0)
Name Forecast_New: 'Time Plan (Lacy))'!$C$1
Name Forecast_New: 'Time Plan (Multiple Release)'!$C$1
Name Forecast_New: 'Time Plan (Partial Phani)'!$C$1
Name Forecast_New: 'Time Plan HY'!$C$1
Name Forecast_New: 'Time Plan (Single Release)'!$C$1
Name forecastdate: #REF!
Name forecastdate_OLD: #REF!
Name Panel: #REF!
Name Panel_New: 'Time Plan (Lacy))'!$F$4
Name Panel_New: 'Time Plan (Multiple Release)'!$F$4
Name Panel_New: 'Time Plan (Partial Phani)'!$F$4
Name Panel_New: 'Time Plan HY'!$F$4
Name Panel_New: 'Time Plan (Single Release)'!$F$4
Name Panel_OLD: #REF!
Name PeopleList: INDEX(CMEMList[Names],0)
Name PeopleList: INDEX(CMEMList[Names],0)
Name PeopleList: INDEX(CMEMList[Names],0)
Name PeopleList: INDEX(CMEMList[Names],0)
Name PeopleList: INDEX(CMEMList[Names],0)
Name ResAugProject: #REF!
Name ResourceNames: CostTableLookup[Name]
Name ResourceNames: CostTableLookup[Name]
Name ResourceNames: CostTableLookup[Name]
Name ResourceNames: CostTableLookup[Name]
Name ResourceNames: CostTableLookup[Name]
Name test: "OFFSET(Plan!T4,0,MATCH(HLOOKUP(TODAY(),Plan!T1:BS1,1,TRUE),Plan!T1:BS1),1,COLUMNS(Plan!T4:BS4)-MATCH(HLOOKUP(TODAY(),Plan!T4:BS4,1,TRUE),Plan!T4:BS4))"

Sheet Coversheet
B1: REASON GROUP ENGAGEMENT JOB PLAN (template updated 25 AUG 2025) | E1: Summary of Requirement
B2: CLIENT INFORMATION | E2: The Attorney-General's Department (the department) is seeking a 12-month contract to supply, software licensing and professional services required to build a Case Management System (CMS). AGD requires a quote for both professional services to build and the software licenses required to deliver the solution (noting: unit pricing is preferred for licenses). The resulting contract will include the ability to purchase additional software licensing and additional professional services relevant to the solution as required. Date expected to place order: Monday, 03 November 2025. Expected contract duration: 12 months. Extension term: 12 months, Number of extensions: 2
B3: Client name | C3: AGD - Attorney-General's Department
B4: Client sponsor (buyer)
B5: Client sponsor email
B6: Client contact phone/mobile number
B7: End client (if different to above)
B8: Work location | C8: Canberra
B9: ENGAGEMENT INFORMATION | E9: Delivery Assumptions
B10: Engagement Code | E10: Hadas: I had a chat with Andy, the most important for this customer is to support their maturity, OCM, how to run a project and get it right etc. We will go with PSDS Pro Plus (Now Assist) on their existing instance. We will get the Servicenow response early next week. We also need to mention how we will work with the managed service provider (he doesn't know who it is yet). He also hasn't heard from Novabridge or Xmplify so maybe they aren't in.
B11: Engagement name | C11: Case Management System (CMS) Licences, Build and Development – Commonwealth Parole Board
B12: Account Manager (pre-populated from Time Plan) | C12: ='Time Plan (Single Release)'!D4 -> Aleksandar Vranesevic
B13: Engagement Manager (pre-populated from Time Plan) | C13: ='Time Plan (Single Release)'!D5 -> Hadas Yehezkel
B14: Timesheets requirement | C14: Signed I-Time
B15: Start date (pre-populated from Time Plan) | C15: ='Time Plan (Single Release)'!C2 -> 46062
B16: End date | C16: 46328
B17: FINANCIAL & ACCOUNT INFORMATION | E17: Pricing Assumptions
B18: PO/WO Number | E18: ServiceNow pricing
B19: PO/WO Amount (ex GST)
B20: Project Budget Amount (ex GST) in iTimes
B21: Variance (Project Budget to PO ex GST) | C21: =C20-C19 -> 0
B22: Variance (Project budget to total task budget ex GST) | C22: =Coversheet!C20-'Time Plan (Single Release)'!M5 -> 0
B23: Accounts Contact
B24: Accounts Email Address
B25: Invoice method
B26: Invoice Instructions (T&M/monthly; Milestones, approvals)
B27: SYSTEM SETUP REQUIREMENT | E27: Identified Risks
B28: MS Teams DEL channel & Planner required | C28: Yes
B29: -> If using existing (insert engagement code)
B31: Legend: | C31: TBC by CAS
C32: TBC by CSD
C33: TBC by OPS

Sheet Pricing
U1: Category | V1: =Category_New -> Market Rates - Solutions implementation services
B2: By Milestone/Workstream | L2: By Deliverable | U2: By Person
B3: Milestone | C3: Start Date | D3: End Date | E3: Week Number | F3: $ ex GST | G3: $ GST | H3: $ inc GST | I3: Discount | J3: Margin | L3: Deliverable | M3: Start Date | N3: End Date | O3: $ ex GST | P3: GST | Q3: $ inc GST | R3: Discount | S3: Margin | U3: Resource | V3: Position | W3: Offered Hourly Rate ($ ex-GST) | X3: Offered Hourly Rate ($ inc-GST) | Y3: Start Date | Z3: End Date | AA3: Chargeable $ ex GST | AB3: Chargeable $ inc GST | AC3: Discount % | AD3: Margin % | AE3: Forecasted Hours | AF3: Forecasted Days | AG3: Re-apportioned Hours (distribute contingency) | AH3: Re-apportioned Days (distribute contingency) | AI3: % Re-allocation of contingency | AJ3: Re-allocated $ ex GST
B4: {=IFERROR(_xlfn._xlws.SORT(_xlfn.UNIQUE(_xlfn._xlws.FILTER('Time Plan (Single Release)'!B6:B64, 'Time Plan (Single Release)'!B6:B64 <> ""))),"")} -> M1 - Discovery Completion | C4: {=IFERROR(INDEX('Time Plan (Single Release)'!$Y$3:$JN$3, 1, _xlfn.XMATCH(TRUE, _xlfn.BYCOL(('Time Plan (Single Release)'!$Y$6:$JN$64)*('Time Plan (Single Release)'!$B$6:$B$64=$B4), _xlfn.LAMBDA(_xlpm.col, SUM(_xlpm.col)>0)), 0, 1)),"")} -> 46062 | D4: {=IFERROR(INDEX('Time Plan (Single Release)'!$Y$3:$JN$3, 1, _xlfn.XMATCH(TRUE, _xlfn.BYCOL(('Time Plan (Single Release)'!$Y$6:$JN$64)*('Time Plan (Single Release)'!$B$6:$B$64=$B4), _xlfn.LAMBDA(_xlpm.col, SUM(_xlpm.col)>0)), 0,-1))+4,"")} -> 46087 | E4: =IFERROR(DATEDIF('Time Plan (Single Release)'!$Y$3,$D4+3,"d")/7,"") -> 4 | F4: {=SUM(IFERROR(('Time Plan (Single Release)'!$U$6:$U$64*('Time Plan (Single Release)'!$B$6:$B$64=Pricing!$B4)),0))} -> 28773.2 | G4: =$F4*0.1 -> 2877.32 | H4: =$F4*1.1 -> 31650.52 | I4: {=IFERROR( (SUM('Time Plan (Single Release)'!$Y$6:$JN$64*(IFERROR('Time Plan (Single Release)'!$G$6:$G$64*40,0))*('Time Plan (Single Release)'!$B$6:$B$64=Pricing!$B4)) - SUM('Time Plan (Single Release)'!$Y$6:$JN$64*(IFERROR('Time Plan (Single Release)'!$I$6:$I$64*40,0))*('Time Plan (Single Release)'!$B$6:$B$64=Pricing!$B4))) / SUM('Time Plan (Single Release)'!$Y$6:$JN$64*(IFERROR('Time Plan (Single Release)'!$G$6:$G$64*40,0))*('Time Plan (Single Release)'!$B$6:$B$64=Pricing!$B4)),"")} -> 0.41381916 | J4: {=IFERROR( (SUM('Time Plan (Single Release)'!$Y$6:$JN$64*(IFERROR('Time Plan (Single Release)'!$I$6:$I$64*40,0))*('Time Plan (Single Release)'!$B$6:$B$64=Pricing!$B4)) - SUM('Time Plan (Single Release)'!$Y$6:$JN$64*(IFERROR('Time Plan (Single Release)'!$K$6:$K$64*40,0))*('Time Plan (Single Release)'!$B$6:$B$64=Pricing!$B4))) / SUM('Time Plan (Single Release)'!$Y$6:$JN$64*(IFERROR('Time Plan (Single Release)'!$I$6:$I$64*40,0))*('Time Plan (Single Release)'!$B$6:$B$64=Pricing!$B4)),"")} -> -0.0067441646 | L4: {=IFERROR(_xlfn._xlws.SORT(_xlfn.UNIQUE(_xlfn._xlws.FILTER('Time Plan (Single Release)'!C6:C64, 'Time Plan (Single Release)'!C6:C64 <> ""))),"")} -> 1.1 Detailed requirements, business process mapping | M4: {=IFERROR(INDEX('Time Plan (Single Release)'!$Y$3:$JN$3, 1, _xlfn.XMATCH(TRUE, _xlfn.BYCOL(('Time Plan (Single Release)'!$Y$6:$JN$64)*('Time Plan (Single Release)'!$C$6:$C$64=$L4), _xlfn.LAMBDA(_xlpm.col, SUM(_xlpm.col)>0)), 0, 1)),"")} -> 46062 | N4: {=IFERROR(INDEX('Time Plan (Single Release)'!$Y$3:$JN$3, 1, _xlfn.XMATCH(TRUE, _xlfn.BYCOL(('Time Plan (Single Release)'!$Y$6:$JN$64)*('Time Plan (Single Release)'!$C$6:$C$64=$L4), _xlfn.LAMBDA(_xlpm.col, SUM(_xlpm.col)>0)), 0,-1))+4,"")} -> 46087 | O4: {=SUM(IFERROR(('Time Plan (Single Release)'!$U$6:$U$64*('Time Plan (Single Release)'!$C$6:$C$64=$L4)),0))} -> 28773.2 | P4: =IFERROR(O4*0.1,"") -> 2877.32 | Q4: =O4*1.1 -> 31650.52 | R4: {=IFERROR( (SUM('Time Plan (Single Release)'!$Y$6:$JN$64*(IFERROR('Time Plan (Single Release)'!$G$6:$G$64*40,0))*('Time Plan (Single Release)'!$C$6:$C$64=$L4)) - SUM('Time Plan (Single Release)'!$Y$6:$JN$64*(IFERROR('Time Plan (Single Release)'!$I$6:$I$64*40,0))*('Time Plan (Single Release)'!$C$6:$C$64=$L4))) / SUM('Time Plan (Single Release)'!$Y$6:$JN$64*(IFERROR('Time Plan (Single Release)'!$G$6:$G$64*40,0))*('Time Plan (Single Release)'!$C$6:$C$64=$L4)),"")} -> 0.41381916 | S4: {=IFERROR( (SUM('Time Plan (Single Release)'!$Y$6:$JN$64*(IFERROR('Time Plan (Single Release)'!$I$6:$I$64*40,0))*('Time Plan (Single Release)'!$C$6:$C$64=$L4)) - SUM('Time Plan (Single Release)'!$Y$6:$JN$64*(IFERROR('Time Plan (Single Release)'!$K$6:$K$64*40,0))*('Time Plan (Single Release)'!$C$6:$C$64=$L4))) / SUM('Time Plan (Single Release)'!$Y$6:$JN$64*(IFERROR('Time Plan (Single Release)'!$I$6:$I$64*40,0))*('Time Plan (Single Release)'!$C$6:$C$64=$L4)),"")} -> -0.0067441646 | U4: {=IFERROR(_xlfn._xlws.SORT(_xlfn.UNIQUE(_xlfn._xlws.FILTER('Time Plan (Single Release)'!D6:D64, 'Time Plan (Single Release)'!D6:D64 <> ""))),"")} -> Anil Kinagi | V4: {=IFERROR(_xlfn.XLOOKUP($U4,'Time Plan (Single Release)'!$D$6:$D$194,'Time Plan (Single Release)'!$E$6:$E$194&" - "&'Time Plan (Single Release)'!$F$6:$F$194),"")} -> Level 4 - Project Manager | W4: =IFERROR(_xlfn.XLOOKUP($U4,'Time Plan (Single Release)'!$D$6:$D$64,'Time Plan (Single Release)'!$I$6:$I$64),"") -> 207.4 | X4: =IFERROR(W4*1.1,"") -> 228.14 | Y4: {=IFERROR(INDEX('Time Plan (Single Release)'!$Y$3:$JN$3, 1, _xlfn.XMATCH(TRUE, _xlfn.BYCOL(('Time Plan (Single Release)'!$Y$6:$JN$64)*('Time Plan (Single Release)'!$D$6:$D$64=$U4), _xlfn.LAMBDA(_xlpm.col, SUM(_xlpm.col)>0)), 0, 1)),"")} -> 46062 | Z4: {=IFERROR(INDEX('Time Plan (Single Release)'!$Y$3:$JN$3, 1, _xlfn.XMATCH(TRUE, _xlfn.BYCOL(('Time Plan (Single Release)'!$Y$6:$JN$64)*('Time Plan (Single Release)'!$D$6:$D$64=$U4), _xlfn.LAMBDA(_xlpm.col, SUM(_xlpm.col)>0)), 0,-1))+4,"")} -> 46220 | AA4: {=SUM(IFERROR(('Time Plan (Single Release)'!$U$6:$U$64*('Time Plan (Single Release)'!$D$6:$D$64=$U4)),0))} -> 146839.2 | AB4: =AA4*1.1 -> 161523.12 | AC4: {=IFERROR( (SUM('Time Plan (Single Release)'!$Y$6:$JN$64*(IFERROR('Time Plan (Single Release)'!$G$6:$G$64*40,0))*('Time Plan (Single Release)'!$D$6:$D$64=$U4)) - SUM('Time Plan (Single Release)'!$Y$6:$JN$64*(IFERROR('Time Plan (Single Release)'!$I$6:$I$64*40,0))*('Time Plan (Single Release)'!$D$6:$D$64=$U4))) / SUM('Time Plan (Single Release)'!$Y$6:$JN$64*(IFERROR('Time Plan (Single Release)'!$G$6:$G$64*40,0))*('Time Plan (Single Release)'!$D$6:$D$64=$U4)),"")} -> 0.32 | AD4: {=IFERROR( (SUM('Time Plan (Single Release)'!$Y$6:$JN$64*(IFERROR('Time Plan (Single Release)'!$I$6:$I$64*40,0))*('Time Plan (Single Release)'!$D$6:$D$64=$U4)) - SUM('Time Plan (Single Release)'!$Y$6:$JN$64*(IFERROR('Time Plan (Single Release)'!$K$6:$K$64*40,0))*('Time Plan (Single Release)'!$D$6:$D$64=$U4))) / SUM('Time Plan (Single Release)'!$Y$6:$JN$64*(IFERROR('Time Plan (Single Release)'!$I$6:$I$64*40,0))*('Time Plan (Single Release)'!$D$6:$D$64=$U4)),"")} -> -0.18129219 | AE4: =SUMIF('Time Plan (Single Release)'!D$6:D$64,Pricing!U4,'Time Plan (Single Release)'!S$6:S$64) -> 708 | AF4: =AE4/8 -> 88.5
B5: M2 - Sprint 1 and 2 completion | C5: {=IFERROR(INDEX('Time Plan (Single Release)'!$Y$3:$JN$3, 1, _xlfn.XMATCH(TRUE, _xlfn.BYCOL(('Time Plan (Single Release)'!$Y$6:$JN$64)*('Time Plan (Single Release)'!$B$6:$B$64=$B5), _xlfn.LAMBDA(_xlpm.col, SUM(_xlpm.col)>0)), 0, 1)),"")} -> 46076 | D5: {=IFERROR(INDEX('Time Plan (Single Release)'!$Y$3:$JN$3, 1, _xlfn.XMATCH(TRUE, _xlfn.BYCOL(('Time Plan (Single Release)'!$Y$6:$JN$64)*('Time Plan (Single Release)'!$B$6:$B$64=$B5), _xlfn.LAMBDA(_xlpm.col, SUM(_xlpm.col)>0)), 0,-1))+4,"")} -> 46108 | E5: =IFERROR(DATEDIF('Time Plan (Single Release)'!$Y$3,$D5+3,"d")/7,"") -> 7 | F5: {=SUM(IFERROR(('Time Plan (Single Release)'!$U$6:$U$64*('Time Plan (Single Release)'!$B$6:$B$64=Pricing!$B5)),0))} -> 166496.4 | G5: =$F5*0.1 -> 16649.64 | H5: =$F5*1.1 -> 183146.04 | I5: {=IFERROR( (SUM('Time Plan (Single Release)'!$Y$6:$JN$64*(IFERROR('Time Plan (Single Release)'!$G$6:$G$64*40,0))*('Time Plan (Single Release)'!$B$6:$B$64=Pricing!$B5)) - SUM('Time Plan (Single Release)'!$Y$6:$JN$64*(IFERROR('Time Plan (Single Release)'!$I$6:$I$64*40,0))*('Time Plan (Single Release)'!$B$6:$B$64=Pricing!$B5))) / SUM('Time Plan (Single Release)'!$Y$6:$JN$64*(IFERROR('Time Plan (Single Release)'!$G$6:$G$64*40,0))*('Time Plan (Single Release)'!$B$6:$B$64=Pricing!$B5)),"")} -> 0.41922343 | J5: {=IFERROR( (SUM('Time Plan (Single Release)'!$Y$6:$JN$64*(IFERROR('Time Plan (Single Release)'!$I$6:$I$64*40,0))*('Time Plan (Single Release)'!$B$6:$B$64=Pricing!$B5)) - SUM('Time Plan (Single Release)'!$Y$6:$JN$64*(IFERROR('Time Plan (Single Release)'!$K$6:$K$64*40,0))*('Time Plan (Single Release)'!$B$6:$B$64=Pricing!$B5))) / SUM('Time Plan (Single Release)'!$Y$6:$JN$64*(IFERROR('Time Plan (Single Release)'!$I$6:$I$64*40,0))*('Time Plan (Single Release)'!$B$6:$B$64=Pricing!$B5)),"")} -> -0.045165699 | L5: 1.3 Detailed delivery plan, RACI of build/delivery meeting AGD Operating Model requirements | M5: {=IFERROR(INDEX('Time Plan (Single Release)'!$Y$3:$JN$3, 1, _xlfn.XMATCH(TRUE, _xlfn.BYCOL(('Time Plan (Single Release)'!$Y$6:$JN$64)*('Time Plan (Single Release)'!$C$6:$C$64=$L5), _xlfn.LAMBDA(_xlpm.col, SUM(_xlpm.col)>0)), 0, 1)),"")} | N5: {=IFERROR(INDEX('Time Plan (Single Release)'!$Y$3:$JN$3, 1, _xlfn.XMATCH(TRUE, _xlfn.BYCOL(('Time Plan (Single Release)'!$Y$6:$JN$64)*('Time Plan (Single Release)'!$C$6:$C$64=$L5), _xlfn.LAMBDA(_xlpm.col, SUM(_xlpm.col)>0)), 0,-1))+4,"")} | O5: {=SUM(IFERROR(('Time Plan (Single Release)'!$U$6:$U$64*('Time Plan (Single Release)'!$C$6:$C$64=$L5)),0))} -> 0 | P5: =IFERROR(O5*0.1,"") -> 0 | Q5: =O5*1.1 -> 0 | R5: {=IFERROR( (SUM('Time Plan (Single Release)'!$Y$6:$JN$64*(IFERROR('Time Plan (Single Release)'!$G$6:$G$64*40,0))*('Time Plan (Single Release)'!$C$6:$C$64=$L5)) - SUM('Time Plan (Single Release)'!$Y$6:$JN$64*(IFERROR('Time Plan (Single Release)'!$I$6:$I$64*40,0))*('Time Plan (Single Release)'!$C$6:$C$64=$L5))) / SUM('Time Plan (Single Release)'!$Y$6:$JN$64*(IFERROR('Time Plan (Single Release)'!$G$6:$G$64*40,0))*('Time Plan (Single Release)'!$C$6:$C$64=$L5)),"")} | S5: {=IFERROR( (SUM('Time Plan (Single Release)'!$Y$6:$JN$64*(IFERROR('Time Plan (Single Release)'!$I$6:$I$64*40,0))*('Time Plan (Single Release)'!$C$6:$C$64=$L5)) - SUM('Time Plan (Single Release)'!$Y$6:$JN$64*(IFERROR('Time Plan (Single Release)'!$K$6:$K$64*40,0))*('Time Plan (Single Release)'!$C$6:$C$64=$L5))) / SUM('Time Plan (Single Release)'!$Y$6:$JN$64*(IFERROR('Time Plan (Single Release)'!$I$6:$I$64*40,0))*('Time Plan (Single Release)'!$C$6:$C$64=$L5)),"")} | U5: Bradley Burge | V5: {=IFERROR(_xlfn.XLOOKUP($U5,'Time Plan (Single Release)'!$D$6:$D$194,'Time Plan (Single Release)'!$E$6:$E$194&" - "&'Time Plan (Single Release)'!$F$6:$F$194),"")} -> Level 4 - Lead ServiceNow Developer | W5: =IFERROR(_xlfn.XLOOKUP($U5,'Time Plan (Single Release)'!$D$6:$D$64,'Time Plan (Single Release)'!$I$6:$I$64),"") -> 207.4 | X5: =IFERROR(W5*1.1,"") -> 228.14 | Y5: {=IFERROR(INDEX('Time Plan (Single Release)'!$Y$3:$JN$3, 1, _xlfn.XMATCH(TRUE, _xlfn.BYCOL(('Time Plan (Single Release)'!$Y$6:$JN$64)*('Time Plan (Single Release)'!$D$6:$D$64=$U5), _xlfn.LAMBDA(_xlpm.col, SUM(_xlpm.col)>0)), 0, 1)),"")} -> 46076 | Z5: {=IFERROR(INDEX('Time Plan (Single Release)'!$Y$3:$JN$3, 1, _xlfn.XMATCH(TRUE, _xlfn.BYCOL(('Time Plan (Single Release)'!$Y$6:$JN$64)*('Time Plan (Single Release)'!$D$6:$D$64=$U5), _xlfn.LAMBDA(_xlpm.col, SUM(_xlpm.col)>0)), 0,-1))+4,"")} -> 46220 | AA5: {=SUM(IFERROR(('Time Plan (Single Release)'!$U$6:$U$64*('Time Plan (Single Release)'!$D$6:$D$64=$U5)),0))} -> 155428 | AB5: =AA5*1.1 -> 170970.8 | AC5: {=IFERROR( (SUM('Time Plan (Single Release)'!$Y$6:$JN$64*(IFERROR('Time Plan (Single Release)'!$G$6:$G$64*40,0))*('Time Plan (Single Release)'!$D$6:$D$64=$U5)) - SUM('Time Plan (Single Release)'!$Y$6:$JN$64*(IFERROR('Time Plan (Single Release)'!$I$6:$I$64*40,0))*('Time Plan (Single Release)'!$D$6:$D$64=$U5))) / SUM('Time Plan (Single Release)'!$Y$6:$JN$64*(IFERROR('Time Plan (Single Release)'!$G$6:$G$64*40,0))*('Time Plan (Single Release)'!$D$6:$D$64=$U5)),"")} -> 0.37714286 | AD5: {=IFERROR( (SUM('Time Plan (Single Release)'!$Y$6:$JN$64*(IFERROR('Time Plan (Single Release)'!$I$6:$I$64*40,0))*('Time Plan (Single Release)'!$D$6:$D$64=$U5)) - SUM('Time Plan (Single Release)'!$Y$6:$JN$64*(IFERROR('Time Plan (Single Release)'!$K$6:$K$64*40,0))*('Time Plan (Single Release)'!$D$6:$D$64=$U5))) / SUM('Time Plan (Single Release)'!$Y$6:$JN$64*(IFERROR('Time Plan (Single Release)'!$I$6:$I$64*40,0))*('Time Plan (Single Release)'!$D$6:$D$64=$U5)),"")} -> 0.20514363 | AE5: =SUMIF('Time Plan (Single Release)'!D$6:D$64,Pricing!U5,'Time Plan (Single Release)'!S$6:S$64) -> 820 | AF5: =AE5/8 -> 102.5 | AG5: =IFERROR(AE5+(AA$4*AI5/W5),"") -> 820 | AH5: =IFERROR(AG5/8,"") -> 102.5 | AI5: 0 | AJ5: =AG5*W5 -> 170068
B6: M3 - Sprint 3 and 4 completion | C6: {=IFERROR(INDEX('Time Plan (Single Release)'!$Y$3:$JN$3, 1, _xlfn.XMATCH(TRUE, _xlfn.BYCOL(('Time Plan (Single Release)'!$Y$6:$JN$64)*('Time Plan (Single Release)'!$B$6:$B$64=$B6), _xlfn.LAMBDA(_xlpm.col, SUM(_xlpm.col)>0)), 0, 1)),"")} -> 46111 | D6: {=IFERROR(INDEX('Time Plan (Single Release)'!$Y$3:$JN$3, 1, _xlfn.XMATCH(TRUE, _xlfn.BYCOL(('Time Plan (Single Release)'!$Y$6:$JN$64)*('Time Plan (Single Release)'!$B$6:$B$64=$B6), _xlfn.LAMBDA(_xlpm.col, SUM(_xlpm.col)>0)), 0,-1))+4,"")} -> 46136 | E6: =IFERROR(DATEDIF('Time Plan (Single Release)'!$Y$3,$D6+3,"d")/7,"") -> 11 | F6: {=SUM(IFERROR(('Time Plan (Single Release)'!$U$6:$U$64*('Time Plan (Single Release)'!$B$6:$B$64=Pricing!$B6)),0))} -> 202558.44 | G6: =$F6*0.1 -> 20255.844 | H6: =$F6*1.1 -> 222814.28 | I6: {=IFERROR( (SUM('Time Plan (Single Release)'!$Y$6:$JN$64*(IFERROR('Time Plan (Single Release)'!$G$6:$G$64*40,0))*('Time Plan (Single Release)'!$B$6:$B$64=Pricing!$B6)) - SUM('Time Plan (Single Release)'!$Y$6:$JN$64*(IFERROR('Time Plan (Single Release)'!$I$6:$I$64*40,0))*('Time Plan (Single Release)'!$B$6:$B$64=Pricing!$B6))) / SUM('Time Plan (Single Release)'!$Y$6:$JN$64*(IFERROR('Time Plan (Single Release)'!$G$6:$G$64*40,0))*('Time Plan (Single Release)'!$B$6:$B$64=Pricing!$B6)),"")} -> 0.37904629 | J6: {=IFERROR( (SUM('Time Plan (Single Release)'!$Y$6:$JN$64*(IFERROR('Time Plan (Single Release)'!$I$6:$I$64*40,0))*('Time Plan (Single Release)'!$B$6:$B$64=Pricing!$B6)) - SUM('Time Plan (Single Release)'!$Y$6:$JN$64*(IFERROR('Time Plan (Single Release)'!$K$6:$K$64*40,0))*('Time Plan (Single Release)'!$B$6:$B$64=Pricing!$B6))) / SUM('Time Plan (Single Release)'!$Y$6:$JN$64*(IFERROR('Time Plan (Single Release)'!$I$6:$I$64*40,0))*('Time Plan (Single Release)'!$B$6:$B$64=Pricing!$B6)),"")} -> 0.034038097 | L6: 1.4 Acceptance certificate | M6: {=IFERROR(INDEX('Time Plan (Single Release)'!$Y$3:$JN$3, 1, _xlfn.XMATCH(TRUE, _xlfn.BYCOL(('Time Plan (Single Release)'!$Y$6:$JN$64)*('Time Plan (Single Release)'!$C$6:$C$64=$L6), _xlfn.LAMBDA(_xlpm.col, SUM(_xlpm.col)>0)), 0, 1)),"")} | N6: {=IFERROR(INDEX('Time Plan (Single Release)'!$Y$3:$JN$3, 1, _xlfn.XMATCH(TRUE, _xlfn.BYCOL(('Time Plan (Single Release)'!$Y$6:$JN$64)*('Time Plan (Single Release)'!$C$6:$C$64=$L6), _xlfn.LAMBDA(_xlpm.col, SUM(_xlpm.col)>0)), 0,-1))+4,"")} | O6: {=SUM(IFERROR(('Time Plan (Single Release)'!$U$6:$U$64*('Time Plan (Single Release)'!$C$6:$C$64=$L6)),0))} -> 0 | P6: =IFERROR(O6*0.1,"") -> 0 | Q6: =O6*1.1 -> 0 | R6: {=IFERROR( (SUM('Time Plan (Single Release)'!$Y$6:$JN$64*(IFERROR('Time Plan (Single Release)'!$G$6:$G$64*40,0))*('Time Plan (Single Release)'!$C$6:$C$64=$L6)) - SUM('Time Plan (Single Release)'!$Y$6:$JN$64*(IFERROR('Time Plan (Single Release)'!$I$6:$I$64*40,0))*('Time Plan (Single Release)'!$C$6:$C$64=$L6))) / SUM('Time Plan (Single Release)'!$Y$6:$JN$64*(IFERROR('Time Plan (Single Release)'!$G$6:$G$64*40,0))*('Time Plan (Single Release)'!$C$6:$C$64=$L6)),"")} | S6: {=IFERROR( (SUM('Time Plan (Single Release)'!$Y$6:$JN$64*(IFERROR('Time Plan (Single Release)'!$I$6:$I$64*40,0))*('Time Plan (Single Release)'!$C$6:$C$64=$L6)) - SUM('Time Plan (Single Release)'!$Y$6:$JN$64*(IFERROR('Time Plan (Single Release)'!$K$6:$K$64*40,0))*('Time Plan (Single Release)'!$C$6:$C$64=$L6))) / SUM('Time Plan (Single Release)'!$Y$6:$JN$64*(IFERROR('Time Plan (Single Release)'!$I$6:$I$64*40,0))*('Time Plan (Single Release)'!$C$6:$C$64=$L6)),"")} | U6: Contingency | V6: {=IFERROR(_xlfn.XLOOKUP($U6,'Time Plan (Single Release)'!$D$6:$D$194,'Time Plan (Single Release)'!$E$6:$E$194&" - "&'Time Plan (Single Release)'!$F$6:$F$194),"")} -> - | W6: =IFERROR(_xlfn.XLOOKUP($U6,'Time Plan (Single Release)'!$D$6:$D$64,'Time Plan (Single Release)'!$I$6:$I$64),"") -> 1438.66 | X6: =IFERROR(W6*1.1,"") -> 1582.526 | Y6: {=IFERROR(INDEX('Time Plan (Single Release)'!$Y$3:$JN$3, 1, _xlfn.XMATCH(TRUE, _xlfn.BYCOL(('Time Plan (Single Release)'!$Y$6:$JN$64)*('Time Plan (Single Release)'!$D$6:$D$64=$U6), _xlfn.LAMBDA(_xlpm.col, SUM(_xlpm.col)>0)), 0, 1)),"")} -> 46069 | Z6: {=IFERROR(INDEX('Time Plan (Single Release)'!$Y$3:$JN$3, 1, _xlfn.XMATCH(TRUE, _xlfn.BYCOL(('Time Plan (Single Release)'!$Y$6:$JN$64)*('Time Plan (Single Release)'!$D$6:$D$64=$U6), _xlfn.LAMBDA(_xlpm.col, SUM(_xlpm.col)>0)), 0,-1))+4,"")} -> 46136 | AA6: {=SUM(IFERROR(('Time Plan (Single Release)'!$U$6:$U$64*('Time Plan (Single Release)'!$D$6:$D$64=$U6)),0))} -> 17574.04 | AB6: =AA6*1.1 -> 19331.444 | AC6: {=IFERROR( (SUM('Time Plan (Single Release)'!$Y$6:$JN$64*(IFERROR('Time Plan (Single Release)'!$G$6:$G$64*40,0))*('Time Plan (Single Release)'!$D$6:$D$64=$U6)) - SUM('Time Plan (Single Release)'!$Y$6:$JN$64*(IFERROR('Time Plan (Single Release)'!$I$6:$I$64*40,0))*('Time Plan (Single Release)'!$D$6:$D$64=$U6))) / SUM('Time Plan (Single Release)'!$Y$6:$JN$64*(IFERROR('Time Plan (Single Release)'!$G$6:$G$64*40,0))*('Time Plan (Single Release)'!$D$6:$D$64=$U6)),"")} | AD6: {=IFERROR( (SUM('Time Plan (Single Release)'!$Y$6:$JN$64*(IFERROR('Time Plan (Single Release)'!$I$6:$I$64*40,0))*('Time Plan (Single Release)'!$D$6:$D$64=$U6)) - SUM('Time Plan (Single Release)'!$Y$6:$JN$64*(IFERROR('Time Plan (Single Release)'!$K$6:$K$64*40,0))*('Time Plan (Single Release)'!$D$6:$D$64=$U6))) / SUM('Time Plan (Single Release)'!$Y$6:$JN$64*(IFERROR('Time Plan (Single Release)'!$I$6:$I$64*40,0))*('Time Plan (Single Release)'!$D$6:$D$64=$U6)),"")} -> 1 | AE6: =SUMIF('Time Plan (Single Release)'!D$6:D$64,Pricing!U6,'Time Plan (Single Release)'!S$6:S$64) -> 3 | AF6: =AE6/8 -> 0.375 | AG6: =IFERROR(AE6+(AA$4*AI6/W6),"") -> 3 | AH6: =IFERROR(AG6/8,"") -> 0.375 | AI6: 0 | AJ6: =AG6*W6 -> 4315.98
B7: M4 - Sprint 5 and 6 completion | C7: {=IFERROR(INDEX('Time Plan (Single Release)'!$Y$3:$JN$3, 1, _xlfn.XMATCH(TRUE, _xlfn.BYCOL(('Time Plan (Single Release)'!$Y$6:$JN$64)*('Time Plan (Single Release)'!$B$6:$B$64=$B7), _xlfn.LAMBDA(_xlpm.col, SUM(_xlpm.col)>0)), 0, 1)),"")} -> 46139 | D7: {=IFERROR(INDEX('Time Plan (Single Release)'!$Y$3:$JN$3, 1, _xlfn.XMATCH(TRUE, _xlfn.BYCOL(('Time Plan (Single Release)'!$Y$6:$JN$64)*('Time Plan (Single Release)'!$B$6:$B$64=$B7), _xlfn.LAMBDA(_xlpm.col, SUM(_xlpm.col)>0)), 0,-1))+4,"")} -> 46164 | E7: =IFERROR(DATEDIF('Time Plan (Single Release)'!$Y$3,$D7+3,"d")/7,"") -> 15 | F7: {=SUM(IFERROR(('Time Plan (Single Release)'!$U$6:$U$64*('Time Plan (Single Release)'!$B$6:$B$64=Pricing!$B7)),0))} -> 212800 | G7: =$F7*0.1 -> 21280 | H7: =$F7*1.1 -> 234080 | I7: {=IFERROR( (SUM('Time Plan (Single Release)'!$Y$6:$JN$64*(IFERROR('Time Plan (Single Release)'!$G$6:$G$64*40,0))*('Time Plan (Single Release)'!$B$6:$B$64=Pricing!$B7)) - SUM('Time Plan (Single Release)'!$Y$6:$JN$64*(IFERROR('Time Plan (Single Release)'!$I$6:$I$64*40,0))*('Time Plan (Single Release)'!$B$6:$B$64=Pricing!$B7))) / SUM('Time Plan (Single Release)'!$Y$6:$JN$64*(IFERROR('Time Plan (Single Release)'!$G$6:$G$64*40,0))*('Time Plan (Single Release)'!$B$6:$B$64=Pricing!$B7)),"")} -> 0.43101604 | J7: {=IFERROR( (SUM('Time Plan (Single Release)'!$Y$6:$JN$64*(IFERROR('Time Plan (Single Release)'!$I$6:$I$64*40,0))*('Time Plan (Single Release)'!$B$6:$B$64=Pricing!$B7)) - SUM('Time Plan (Single Release)'!$Y$6:$JN$64*(IFERROR('Time Plan (Single Release)'!$K$6:$K$64*40,0))*('Time Plan (Single Release)'!$B$6:$B$64=Pricing!$B7))) / SUM('Time Plan (Single Release)'!$Y$6:$JN$64*(IFERROR('Time Plan (Single Release)'!$I$6:$I$64*40,0))*('Time Plan (Single Release)'!$B$6:$B$64=Pricing!$B7)),"")} -> -0.06162406 | L7: 2.1 Project management and compliance documentation | M7: {=IFERROR(INDEX('Time Plan (Single Release)'!$Y$3:$JN$3, 1, _xlfn.XMATCH(TRUE, _xlfn.BYCOL(('Time Plan (Single Release)'!$Y$6:$JN$64)*('Time Plan (Single Release)'!$C$6:$C$64=$L7), _xlfn.LAMBDA(_xlpm.col, SUM(_xlpm.col)>0)), 0, 1)),"")} -> 46083 | N7: {=IFERROR(INDEX('Time Plan (Single Release)'!$Y$3:$JN$3, 1, _xlfn.XMATCH(TRUE, _xlfn.BYCOL(('Time Plan (Single Release)'!$Y$6:$JN$64)*('Time Plan (Single Release)'!$C$6:$C$64=$L7), _xlfn.LAMBDA(_xlpm.col, SUM(_xlpm.col)>0)), 0,-1))+4,"")} -> 46220 | O7: {=SUM(IFERROR(('Time Plan (Single Release)'!$U$6:$U$64*('Time Plan (Single Release)'!$C$6:$C$64=$L7)),0))} -> 227755.2 | P7: =IFERROR(O7*0.1,"") -> 22775.52 | Q7: =O7*1.1 -> 250530.72 | R7: {=IFERROR( (SUM('Time Plan (Single Release)'!$Y$6:$JN$64*(IFERROR('Time Plan (Single Release)'!$G$6:$G$64*40,0))*('Time Plan (Single Release)'!$C$6:$C$64=$L7)) - SUM('Time Plan (Single Release)'!$Y$6:$JN$64*(IFERROR('Time Plan (Single Release)'!$I$6:$I$64*40,0))*('Time Plan (Single Release)'!$C$6:$C$64=$L7))) / SUM('Time Plan (Single Release)'!$Y$6:$JN$64*(IFERROR('Time Plan (Single Release)'!$G$6:$G$64*40,0))*('Time Plan (Single Release)'!$C$6:$C$64=$L7)),"")} -> 0.34372061 | S7: {=IFERROR( (SUM('Time Plan (Single Release)'!$Y$6:$JN$64*(IFERROR('Time Plan (Single Release)'!$I$6:$I$64*40,0))*('Time Plan (Single Release)'!$C$6:$C$64=$L7)) - SUM('Time Plan (Single Release)'!$Y$6:$JN$64*(IFERROR('Time Plan (Single Release)'!$K$6:$K$64*40,0))*('Time Plan (Single Release)'!$C$6:$C$64=$L7))) / SUM('Time Plan (Single Release)'!$Y$6:$JN$64*(IFERROR('Time Plan (Single Release)'!$I$6:$I$64*40,0))*('Time Plan (Single Release)'!$C$6:$C$64=$L7)),"")} -> 0.0091115373 | U7: Contractor-Tester-Manager | V7: {=IFERROR(_xlfn.XLOOKUP($U7,'Time Plan (Single Release)'!$D$6:$D$194,'Time Plan (Single Release)'!$E$6:$E$194&" - "&'Time Plan (Single Release)'!$F$6:$F$194),"")} -> Level 3 - Senior Tester | W7: =IFERROR(_xlfn.XLOOKUP($U7,'Time Plan (Single Release)'!$D$6:$D$64,'Time Plan (Single Release)'!$I$6:$I$64),"") -> 151.9 | X7: =IFERROR(W7*1.1,"") -> 167.09 | Y7: {=IFERROR(INDEX('Time Plan (Single Release)'!$Y$3:$JN$3, 1, _xlfn.XMATCH(TRUE, _xlfn.BYCOL(('Time Plan (Single Release)'!$Y$6:$JN$64)*('Time Plan (Single Release)'!$D$6:$D$64=$U7), _xlfn.LAMBDA(_xlpm.col, SUM(_xlpm.col)>0)), 0, 1)),"")} -> 46125 | Z7: {=IFERROR(INDEX('Time Plan (Single Release)'!$Y$3:$JN$3, 1, _xlfn.XMATCH(TRUE, _xlfn.BYCOL(('Time Plan (Single Release)'!$Y$6:$JN$64)*('Time Plan (Single Release)'!$D$6:$D$64=$U7), _xlfn.LAMBDA(_xlpm.col, SUM(_xlpm.col)>0)), 0,-1))+4,"")} -> 46192 | AA7: {=SUM(IFERROR(('Time Plan (Single Release)'!$U$6:$U$64*('Time Plan (Single Release)'!$D$6:$D$64=$U7)),0))} -> 60760 | AB7: =AA7*1.1 -> 66836 | AC7: {=IFERROR( (SUM('Time Plan (Single Release)'!$Y$6:$JN$64*(IFERROR('Time Plan (Single Release)'!$G$6:$G$64*40,0))*('Time Plan (Single Release)'!$D$6:$D$64=$U7)) - SUM('Time Plan (Single Release)'!$Y$6:$JN$64*(IFERROR('Time Plan (Single Release)'!$I$6:$I$64*40,0))*('Time Plan (Single Release)'!$D$6:$D$64=$U7))) / SUM('Time Plan (Single Release)'!$Y$6:$JN$64*(IFERROR('Time Plan (Single Release)'!$G$6:$G$64*40,0))*('Time Plan (Single Release)'!$D$6:$D$64=$U7)),"")} -> 0.38 | AD7: {=IFERROR( (SUM('Time Plan (Single Release)'!$Y$6:$JN$64*(IFERROR('Time Plan (Single Release)'!$I$6:$I$64*40,0))*('Time Plan (Single Release)'!$D$6:$D$64=$U7)) - SUM('Time Plan (Single Release)'!$Y$6:$JN$64*(IFERROR('Time Plan (Single Release)'!$K$6:$K$64*40,0))*('Time Plan (Single Release)'!$D$6:$D$64=$U7))) / SUM('Time Plan (Single Release)'!$Y$6:$JN$64*(IFERROR('Time Plan (Single Release)'!$I$6:$I$64*40,0))*('Time Plan (Single Release)'!$D$6:$D$64=$U7)),"")} -> -0.059907834 | AE7: =SUMIF('Time Plan (Single Release)'!D$6:D$64,Pricing!U7,'Time Plan (Single Release)'!S$6:S$64) -> 400 | AF7: =AE7/8 -> 50 | AG7: =IFERROR(AE7+(AA$4*AI7/W7),"") -> 883.34167 | AH7: =IFERROR(AG7/8,"") -> 110.41771 | AI7: 0.5 | AJ7: =AG7*W7 -> 134179.6
B8: M5 - Test Completion & Go-live | C8: {=IFERROR(INDEX('Time Plan (Single Release)'!$Y$3:$JN$3, 1, _xlfn.XMATCH(TRUE, _xlfn.BYCOL(('Time Plan (Single Release)'!$Y$6:$JN$64)*('Time Plan (Single Release)'!$B$6:$B$64=$B8), _xlfn.LAMBDA(_xlpm.col, SUM(_xlpm.col)>0)), 0, 1)),"")} -> 46167 | D8: {=IFERROR(INDEX('Time Plan (Single Release)'!$Y$3:$JN$3, 1, _xlfn.XMATCH(TRUE, _xlfn.BYCOL(('Time Plan (Single Release)'!$Y$6:$JN$64)*('Time Plan (Single Release)'!$B$6:$B$64=$B8), _xlfn.LAMBDA(_xlpm.col, SUM(_xlpm.col)>0)), 0,-1))+4,"")} -> 46192 | E8: =IFERROR(DATEDIF('Time Plan (Single Release)'!$Y$3,$D8+3,"d")/7,"") -> 19 | F8: {=SUM(IFERROR(('Time Plan (Single Release)'!$U$6:$U$64*('Time Plan (Single Release)'!$B$6:$B$64=Pricing!$B8)),0))} -> 112048 | G8: =$F8*0.1 -> 11204.8 | H8: =$F8*1.1 -> 123252.8 | I8: {=IFERROR( (SUM('Time Plan (Single Release)'!$Y$6:$JN$64*(IFERROR('Time Plan (Single Release)'!$G$6:$G$64*40,0))*('Time Plan (Single Release)'!$B$6:$B$64=Pricing!$B8)) - SUM('Time Plan (Single Release)'!$Y$6:$JN$64*(IFERROR('Time Plan (Single Release)'!$I$6:$I$64*40,0))*('Time Plan (Single Release)'!$B$6:$B$64=Pricing!$B8))) / SUM('Time Plan (Single Release)'!$Y$6:$JN$64*(IFERROR('Time Plan (Single Release)'!$G$6:$G$64*40,0))*('Time Plan (Single Release)'!$B$6:$B$64=Pricing!$B8)),"")} -> 0.4544888 | J8: {=IFERROR( (SUM('Time Plan (Single Release)'!$Y$6:$JN$64*(IFERROR('Time Plan (Single Release)'!$I$6:$I$64*40,0))*('Time Plan (Single Release)'!$B$6:$B$64=Pricing!$B8)) - SUM('Time Plan (Single Release)'!$Y$6:$JN$64*(IFERROR('Time Plan (Single Release)'!$K$6:$K$64*40,0))*('Time Plan (Single Release)'!$B$6:$B$64=Pricing!$B8))) / SUM('Time Plan (Single Release)'!$Y$6:$JN$64*(IFERROR('Time Plan (Single Release)'!$I$6:$I$64*40,0))*('Time Plan (Single Release)'!$B$6:$B$64=Pricing!$B8)),"")} -> -0.21947737 | L8: 2.2 Build | M8: {=IFERROR(INDEX('Time Plan (Single Release)'!$Y$3:$JN$3, 1, _xlfn.XMATCH(TRUE, _xlfn.BYCOL(('Time Plan (Single Release)'!$Y$6:$JN$64)*('Time Plan (Single Release)'!$C$6:$C$64=$L8), _xlfn.LAMBDA(_xlpm.col, SUM(_xlpm.col)>0)), 0, 1)),"")} -> 46076 | N8: {=IFERROR(INDEX('Time Plan (Single Release)'!$Y$3:$JN$3, 1, _xlfn.XMATCH(TRUE, _xlfn.BYCOL(('Time Plan (Single Release)'!$Y$6:$JN$64)*('Time Plan (Single Release)'!$C$6:$C$64=$L8), _xlfn.LAMBDA(_xlpm.col, SUM(_xlpm.col)>0)), 0,-1))+4,"")} -> 46220 | O8: {=SUM(IFERROR(('Time Plan (Single Release)'!$U$6:$U$64*('Time Plan (Single Release)'!$C$6:$C$64=$L8)),0))} -> 518242.04 | P8: =IFERROR(O8*0.1,"") -> 51824.204 | Q8: =O8*1.1 -> 570066.24 | R8: {=IFERROR( (SUM('Time Plan (Single Release)'!$Y$6:$JN$64*(IFERROR('Time Plan (Single Release)'!$G$6:$G$64*40,0))*('Time Plan (Single Release)'!$C$6:$C$64=$L8)) - SUM('Time Plan (Single Release)'!$Y$6:$JN$64*(IFERROR('Time Plan (Single Release)'!$I$6:$I$64*40,0))*('Time Plan (Single Release)'!$C$6:$C$64=$L8))) / SUM('Time Plan (Single Release)'!$Y$6:$JN$64*(IFERROR('Time Plan (Single Release)'!$G$6:$G$64*40,0))*('Time Plan (Single Release)'!$C$6:$C$64=$L8)),"")} -> 0.44557628 | S8: {=IFERROR( (SUM('Time Plan (Single Release)'!$Y$6:$JN$64*(IFERROR('Time Plan (Single Release)'!$I$6:$I$64*40,0))*('Time Plan (Single Release)'!$C$6:$C$64=$L8)) - SUM('Time Plan (Single Release)'!$Y$6:$JN$64*(IFERROR('Time Plan (Single Release)'!$K$6:$K$64*40,0))*('Time Plan (Single Release)'!$C$6:$C$64=$L8))) / SUM('Time Plan (Single Release)'!$Y$6:$JN$64*(IFERROR('Time Plan (Single Release)'!$I$6:$I$64*40,0))*('Time Plan (Single Release)'!$C$6:$C$64=$L8)),"")} -> -0.084507967 | U8: Hadas Yehezkel | V8: {=IFERROR(_xlfn.XLOOKUP($U8,'Time Plan (Single Release)'!$D$6:$D$194,'Time Plan (Single Release)'!$E$6:$E$194&" - "&'Time Plan (Single Release)'!$F$6:$F$194),"")} -> Level 5 - ServiceNow Architect | W8: =IFERROR(_xlfn.XLOOKUP($U8,'Time Plan (Single Release)'!$D$6:$D$64,'Time Plan (Single Release)'!$I$6:$I$64),"") -> 237 | X8: =IFERROR(W8*1.1,"") -> 260.7 | Y8: {=IFERROR(INDEX('Time Plan (Single Release)'!$Y$3:$JN$3, 1, _xlfn.XMATCH(TRUE, _xlfn.BYCOL(('Time Plan (Single Release)'!$Y$6:$JN$64)*('Time Plan (Single Release)'!$D$6:$D$64=$U8), _xlfn.LAMBDA(_xlpm.col, SUM(_xlpm.col)>0)), 0, 1)),"")} -> 46062 | Z8: {=IFERROR(INDEX('Time Plan (Single Release)'!$Y$3:$JN$3, 1, _xlfn.XMATCH(TRUE, _xlfn.BYCOL(('Time Plan (Single Release)'!$Y$6:$JN$64)*('Time Plan (Single Release)'!$D$6:$D$64=$U8), _xlfn.LAMBDA(_xlpm.col, SUM(_xlpm.col)>0)), 0,-1))+4,"")} -> 46164 | AA8: {=SUM(IFERROR(('Time Plan (Single Release)'!$U$6:$U$64*('Time Plan (Single Release)'!$D$6:$D$64=$U8)),0))} -> 54510 | AB8: =AA8*1.1 -> 59961 | AC8: {=IFERROR( (SUM('Time Plan (Single Release)'!$Y$6:$JN$64*(IFERROR('Time Plan (Single Release)'!$G$6:$G$64*40,0))*('Time Plan (Single Release)'!$D$6:$D$64=$U8)) - SUM('Time Plan (Single Release)'!$Y$6:$JN$64*(IFERROR('Time Plan (Single Release)'!$I$6:$I$64*40,0))*('Time Plan (Single Release)'!$D$6:$D$64=$U8))) / SUM('Time Plan (Single Release)'!$Y$6:$JN$64*(IFERROR('Time Plan (Single Release)'!$G$6:$G$64*40,0))*('Time Plan (Single Release)'!$D$6:$D$64=$U8)),"")} -> 0.4 | AD8: {=IFERROR( (SUM('Time Plan (Single Release)'!$Y$6:$JN$64*(IFERROR('Time Plan (Single Release)'!$I$6:$I$64*40,0))*('Time Plan (Single Release)'!$D$6:$D$64=$U8)) - SUM('Time Plan (Single Release)'!$Y$6:$JN$64*(IFERROR('Time Plan (Single Release)'!$K$6:$K$64*40,0))*('Time Plan (Single Release)'!$D$6:$D$64=$U8))) / SUM('Time Plan (Single Release)'!$Y$6:$JN$64*(IFERROR('Time Plan (Single Release)'!$I$6:$I$64*40,0))*('Time Plan (Single Release)'!$D$6:$D$64=$U8)),"")} -> 0.16455696 | AE8: =SUMIF('Time Plan (Single Release)'!D$6:D$64,Pricing!U8,'Time Plan (Single Release)'!S$6:S$64) -> 230 | AF8: =AE8/8 -> 28.75 | AG8: =IFERROR(AE8+(AA$4*AI8/W8),"") -> 539.78734 | AH8: =IFERROR(AG8/8,"") -> 67.473418 | AI8: 0.5 | AJ8: =AG8*W8 -> 127929.6
B9: M6 - Hypercare completion | C9: {=IFERROR(INDEX('Time Plan (Single Release)'!$Y$3:$JN$3, 1, _xlfn.XMATCH(TRUE, _xlfn.BYCOL(('Time Plan (Single Release)'!$Y$6:$JN$64)*('Time Plan (Single Release)'!$B$6:$B$64=$B9), _xlfn.LAMBDA(_xlpm.col, SUM(_xlpm.col)>0)), 0, 1)),"")} -> 46195 | D9: {=IFERROR(INDEX('Time Plan (Single Release)'!$Y$3:$JN$3, 1, _xlfn.XMATCH(TRUE, _xlfn.BYCOL(('Time Plan (Single Release)'!$Y$6:$JN$64)*('Time Plan (Single Release)'!$B$6:$B$64=$B9), _xlfn.LAMBDA(_xlpm.col, SUM(_xlpm.col)>0)), 0,-1))+4,"")} -> 46220 | E9: =IFERROR(DATEDIF('Time Plan (Single Release)'!$Y$3,$D9+3,"d")/7,"") -> 23 | F9: {=SUM(IFERROR(('Time Plan (Single Release)'!$U$6:$U$64*('Time Plan (Single Release)'!$B$6:$B$64=Pricing!$B9)),0))} -> 52094.4 | G9: =$F9*0.1 -> 5209.44 | H9: =$F9*1.1 -> 57303.84 | I9: {=IFERROR( (SUM('Time Plan (Single Release)'!$Y$6:$JN$64*(IFERROR('Time Plan (Single Release)'!$G$6:$G$64*40,0))*('Time Plan (Single Release)'!$B$6:$B$64=Pricing!$B9)) - SUM('Time Plan (Single Release)'!$Y$6:$JN$64*(IFERROR('Time Plan (Single Release)'!$I$6:$I$64*40,0))*('Time Plan (Single Release)'!$B$6:$B$64=Pricing!$B9))) / SUM('Time Plan (Single Release)'!$Y$6:$JN$64*(IFERROR('Time Plan (Single Release)'!$G$6:$G$64*40,0))*('Time Plan (Single Release)'!$B$6:$B$64=Pricing!$B9)),"")} -> 0.43115964 | J9: {=IFERROR( (SUM('Time Plan (Single Release)'!$Y$6:$JN$64*(IFERROR('Time Plan (Single Release)'!$I$6:$I$64*40,0))*('Time Plan (Single Release)'!$B$6:$B$64=Pricing!$B9)) - SUM('Time Plan (Single Release)'!$Y$6:$JN$64*(IFERROR('Time Plan (Single Release)'!$K$6:$K$64*40,0))*('Time Plan (Single Release)'!$B$6:$B$64=Pricing!$B9))) / SUM('Time Plan (Single Release)'!$Y$6:$JN$64*(IFERROR('Time Plan (Single Release)'!$I$6:$I$64*40,0))*('Time Plan (Single Release)'!$B$6:$B$64=Pricing!$B9)),"")} -> -0.089176572 | M9: {=IFERROR(INDEX('Time Plan (Single Release)'!$Y$3:$JN$3, 1, _xlfn.XMATCH(TRUE, _xlfn.BYCOL(('Time Plan (Single Release)'!$Y$6:$JN$64)*('Time Plan (Single Release)'!$C$6:$C$64=$L9), _xlfn.LAMBDA(_xlpm.col, SUM(_xlpm.col)>0)), 0, 1)),"")} | N9: {=IFERROR(INDEX('Time Plan (Single Release)'!$Y$3:$JN$3, 1, _xlfn.XMATCH(TRUE, _xlfn.BYCOL(('Time Plan (Single Release)'!$Y$6:$JN$64)*('Time Plan (Single Release)'!$C$6:$C$64=$L9), _xlfn.LAMBDA(_xlpm.col, SUM(_xlpm.col)>0)), 0,-1))+4,"")} | O9: {=SUM(IFERROR(('Time Plan (Single Release)'!$U$6:$U$64*('Time Plan (Single Release)'!$C$6:$C$64=$L9)),0))} -> 0 | P9: =IFERROR(O9*0.1,"") -> 0 | Q9: =O9*1.1 -> 0 | R9: {=IFERROR( (SUM('Time Plan (Single Release)'!$Y$6:$JN$64*(IFERROR('Time Plan (Single Release)'!$G$6:$G$64*40,0))*('Time Plan (Single Release)'!$C$6:$C$64=$L9)) - SUM('Time Plan (Single Release)'!$Y$6:$JN$64*(IFERROR('Time Plan (Single Release)'!$I$6:$I$64*40,0))*('Time Plan (Single Release)'!$C$6:$C$64=$L9))) / SUM('Time Plan (Single Release)'!$Y$6:$JN$64*(IFERROR('Time Plan (Single Release)'!$G$6:$G$64*40,0))*('Time Plan (Single Release)'!$C$6:$C$64=$L9)),"")} | S9: {=IFERROR( (SUM('Time Plan (Single Release)'!$Y$6:$JN$64*(IFERROR('Time Plan (Single Release)'!$I$6:$I$64*40,0))*('Time Plan (Single Release)'!$C$6:$C$64=$L9)) - SUM('Time Plan (Single Release)'!$Y$6:$JN$64*(IFERROR('Time Plan (Single Release)'!$K$6:$K$64*40,0))*('Time Plan (Single Release)'!$C$6:$C$64=$L9))) / SUM('Time Plan (Single Release)'!$Y$6:$JN$64*(IFERROR('Time Plan (Single Release)'!$I$6:$I$64*40,0))*('Time Plan (Single Release)'!$C$6:$C$64=$L9)),"")} | U9: Kosta Walker-Laskos | V9: {=IFERROR(_xlfn.XLOOKUP($U9,'Time Plan (Single Release)'!$D$6:$D$194,'Time Plan (Single Release)'!$E$6:$E$194&" - "&'Time Plan (Single Release)'!$F$6:$F$194),"")} -> Level 3 - ServiceNow Developer | W9: =IFERROR(_xlfn.XLOOKUP($U9,'Time Plan (Single Release)'!$D$6:$D$64,'Time Plan (Single Release)'!$I$6:$I$64),"") -> 151.9 | X9: =IFERROR(W9*1.1,"") -> 167.09 | Y9: {=IFERROR(INDEX('Time Plan (Single Release)'!$Y$3:$JN$3, 1, _xlfn.XMATCH(TRUE, _xlfn.BYCOL(('Time Plan (Single Release)'!$Y$6:$JN$64)*('Time Plan (Single Release)'!$D$6:$D$64=$U9), _xlfn.LAMBDA(_xlpm.col, SUM(_xlpm.col)>0)), 0, 1)),"")} -> 46083 | Z9: {=IFERROR(INDEX('Time Plan (Single Release)'!$Y$3:$JN$3, 1, _xlfn.XMATCH(TRUE, _xlfn.BYCOL(('Time Plan (Single Release)'!$Y$6:$JN$64)*('Time Plan (Single Release)'!$D$6:$D$64=$U9), _xlfn.LAMBDA(_xlpm.col, SUM(_xlpm.col)>0)), 0,-1))+4,"")} -> 46206 | AA9: {=SUM(IFERROR(('Time Plan (Single Release)'!$U$6:$U$64*('Time Plan (Single Release)'!$D$6:$D$64=$U9)),0))} -> 91140 | AB9: =AA9*1.1 -> 100254 | AC9: {=IFERROR( (SUM('Time Plan (Single Release)'!$Y$6:$JN$64*(IFERROR('Time Plan (Single Release)'!$G$6:$G$64*40,0))*('Time Plan (Single Release)'!$D$6:$D$64=$U9)) - SUM('Time Plan (Single Release)'!$Y$6:$JN$64*(IFERROR('Time Plan (Single Release)'!$I$6:$I$64*40,0))*('Time Plan (Single Release)'!$D$6:$D$64=$U9))) / SUM('Time Plan (Single Release)'!$Y$6:$JN$64*(IFERROR('Time Plan (Single Release)'!$G$6:$G$64*40,0))*('Time Plan (Single Release)'!$D$6:$D$64=$U9)),"")} -> 0.38 | AD9: {=IFERROR( (SUM('Time Plan (Single Release)'!$Y$6:$JN$64*(IFERROR('Time Plan (Single Release)'!$I$6:$I$64*40,0))*('Time Plan (Single Release)'!$D$6:$D$64=$U9)) - SUM('Time Plan (Single Release)'!$Y$6:$JN$64*(IFERROR('Time Plan (Single Release)'!$K$6:$K$64*40,0))*('Time Plan (Single Release)'!$D$6:$D$64=$U9))) / SUM('Time Plan (Single Release)'!$Y$6:$JN$64*(IFERROR('Time Plan (Single Release)'!$I$6:$I$64*40,0))*('Time Plan (Single Release)'!$D$6:$D$64=$U9)),"")} -> 0.0059249506 | AE9: =SUMIF('Time Plan (Single Release)'!D$6:D$64,Pricing!U9,'Time Plan (Single Release)'!S$6:S$64) -> 600 | AF9: =AE9/8 -> 75 | AG9: =IFERROR(AE9+(AA$4*AI9/W9),"") -> 600 | AH9: =IFERROR(AG9/8,"") -> 75 | AI9: 0 | AJ9: =AG9*W9 -> 91140
C10: {=IFERROR(INDEX('Time Plan (Single Release)'!$Y$3:$JN$3, 1, _xlfn.XMATCH(TRUE, _xlfn.BYCOL(('Time Plan (Single Release)'!$Y$6:$JN$64)*('Time Plan (Single Release)'!$B$6:$B$64=$B10), _xlfn.LAMBDA(_xlpm.col, SUM(_xlpm.col)>0)), 0, 1)),"")} | D10: {=IFERROR(INDEX('Time Plan (Single Release)'!$Y$3:$JN$3, 1, _xlfn.XMATCH(TRUE, _xlfn.BYCOL(('Time Plan (Single Release)'!$Y$6:$JN$64)*('Time Plan (Single Release)'!$B$6:$B$64=$B10), _xlfn.LAMBDA(_xlpm.col, SUM(_xlpm.col)>0)), 0,-1))+4,"")} | E10: =IFERROR(DATEDIF('Time Plan (Single Release)'!$Y$3,$D10+3,"d")/7,"") | F10: {=SUM(IFERROR(('Time Plan (Single Release)'!$U$6:$U$64*('Time Plan (Single Release)'!$B$6:$B$64=Pricing!$B10)),0))} -> 0 | G10: =$F10*0.1 -> 0 | H10: =$F10*1.1 -> 0 | I10: {=IFERROR( (SUM('Time Plan (Single Release)'!$Y$6:$JN$64*(IFERROR('Time Plan (Single Release)'!$G$6:$G$64*40,0))*('Time Plan (Single Release)'!$B$6:$B$64=Pricing!$B10)) - SUM('Time Plan (Single Release)'!$Y$6:$JN$64*(IFERROR('Time Plan (Single Release)'!$I$6:$I$64*40,0))*('Time Plan (Single Release)'!$B$6:$B$64=Pricing!$B10))) / SUM('Time Plan (Single Release)'!$Y$6:$JN$64*(IFERROR('Time Plan (Single Release)'!$G$6:$G$64*40,0))*('Time Plan (Single Release)'!$B$6:$B$64=Pricing!$B10)),"")} | J10: {=IFERROR( (SUM('Time Plan (Single Release)'!$Y$6:$JN$64*(IFERROR('Time Plan (Single Release)'!$I$6:$I$64*40,0))*('Time Plan (Single Release)'!$B$6:$B$64=Pricing!$B10)) - SUM('Time Plan (Single Release)'!$Y$6:$JN$64*(IFERROR('Time Plan (Single Release)'!$K$6:$K$64*40,0))*('Time Plan (Single Release)'!$B$6:$B$64=Pricing!$B10))) / SUM('Time Plan (Single Release)'!$Y$6:$JN$64*(IFERROR('Time Plan (Single Release)'!$I$6:$I$64*40,0))*('Time Plan (Single Release)'!$B$6:$B$64=Pricing!$B10)),"")} | M10: {=IFERROR(INDEX('Time Plan (Single Release)'!$Y$3:$JN$3, 1, _xlfn.XMATCH(TRUE, _xlfn.BYCOL(('Time Plan (Single Release)'!$Y$6:$JN$64)*('Time Plan (Single Release)'!$C$6:$C$64=$L10), _xlfn.LAMBDA(_xlpm.col, SUM(_xlpm.col)>0)), 0, 1)),"")} | N10: {=IFERROR(INDEX('Time Plan (Single Release)'!$Y$3:$JN$3, 1, _xlfn.XMATCH(TRUE, _xlfn.BYCOL(('Time Plan (Single Release)'!$Y$6:$JN$64)*('Time Plan (Single Release)'!$C$6:$C$64=$L10), _xlfn.LAMBDA(_xlpm.col, SUM(_xlpm.col)>0)), 0,-1))+4,"")} | O10: {=SUM(IFERROR(('Time Plan (Single Release)'!$U$6:$U$64*('Time Plan (Single Release)'!$C$6:$C$64=$L10)),0))} -> 0 | P10: =IFERROR(O10*0.1,"") -> 0 | Q10: =O10*1.1 -> 0 | R10: {=IFERROR( (SUM('Time Plan (Single Release)'!$Y$6:$JN$64*(IFERROR('Time Plan (Single Release)'!$G$6:$G$64*40,0))*('Time Plan (Single Release)'!$C$6:$C$64=$L10)) - SUM('Time Plan (Single Release)'!$Y$6:$JN$64*(IFERROR('Time Plan (Single Release)'!$I$6:$I$64*40,0))*('Time Plan (Single Release)'!$C$6:$C$64=$L10))) / SUM('Time Plan (Single Release)'!$Y$6:$JN$64*(IFERROR('Time Plan (Single Release)'!$G$6:$G$64*40,0))*('Time Plan (Single Release)'!$C$6:$C$64=$L10)),"")} | S10: {=IFERROR( (SUM('Time Plan (Single Release)'!$Y$6:$JN$64*(IFERROR('Time Plan (Single Release)'!$I$6:$I$64*40,0))*('Time Plan (Single Release)'!$C$6:$C$64=$L10)) - SUM('Time Plan (Single Release)'!$Y$6:$JN$64*(IFERROR('Time Plan (Single Release)'!$K$6:$K$64*40,0))*('Time Plan (Single Release)'!$C$6:$C$64=$L10))) / SUM('Time Plan (Single Release)'!$Y$6:$JN$64*(IFERROR('Time Plan (Single Release)'!$I$6:$I$64*40,0))*('Time Plan (Single Release)'!$C$6:$C$64=$L10)),"")} | U10: Lacy Pejcinovic | V10: {=IFERROR(_xlfn.XLOOKUP($U10,'Time Plan (Single Release)'!$D$6:$D$194,'Time Plan (Single Release)'!$E$6:$E$194&" - "&'Time Plan (Single Release)'!$F$6:$F$194),"")} -> Level 3 - Business Analyst | W10: =IFERROR(_xlfn.XLOOKUP($U10,'Time Plan (Single Release)'!$D$6:$D$64,'Time Plan (Single Release)'!$I$6:$I$64),"") -> 151.9 | X10: =IFERROR(W10*1.1,"") -> 167.09 | Y10: {=IFERROR(INDEX('Time Plan (Single Release)'!$Y$3:$JN$3, 1, _xlfn.XMATCH(TRUE, _xlfn.BYCOL(('Time Plan (Single Release)'!$Y$6:$JN$64)*('Time Plan (Single Release)'!$D$6:$D$64=$U10), _xlfn.LAMBDA(_xlpm.col, SUM(_xlpm.col)>0)), 0, 1)),"")} -> 46062 | Z10: {=IFERROR(INDEX('Time Plan (Single Release)'!$Y$3:$JN$3, 1, _xlfn.XMATCH(TRUE, _xlfn.BYCOL(('Time Plan (Single Release)'!$Y$6:$JN$64)*('Time Plan (Single Release)'!$D$6:$D$64=$U10), _xlfn.LAMBDA(_xlpm.col, SUM(_xlpm.col)>0)), 0,-1))+4,"")} -> 46108 | AA10: {=SUM(IFERROR(('Time Plan (Single Release)'!$U$6:$U$64*('Time Plan (Single Release)'!$D$6:$D$64=$U10)),0))} -> 24304 | AB10: =AA10*1.1 -> 26734.4 | AC10: {=IFERROR( (SUM('Time Plan (Single Release)'!$Y$6:$JN$64*(IFERROR('Time Plan (Single Release)'!$G$6:$G$64*40,0))*('Time Plan (Single Release)'!$D$6:$D$64=$U10)) - SUM('Time Plan (Single Release)'!$Y$6:$JN$64*(IFERROR('Time Plan (Single Release)'!$I$6:$I$64*40,0))*('Time Plan (Single Release)'!$D$6:$D$64=$U10))) / SUM('Time Plan (Single Release)'!$Y$6:$JN$64*(IFERROR('Time Plan (Single Release)'!$G$6:$G$64*40,0))*('Time Plan (Single Release)'!$D$6:$D$64=$U10)),"")} -> 0.38 | AD10: {=IFERROR( (SUM('Time Plan (Single Release)'!$Y$6:$JN$64*(IFERROR('Time Plan (Single Release)'!$I$6:$I$64*40,0))*('Time Plan (Single Release)'!$D$6:$D$64=$U10)) - SUM('Time Plan (Single Release)'!$Y$6:$JN$64*(IFERROR('Time Plan (Single Release)'!$K$6:$K$64*40,0))*('Time Plan (Single Release)'!$D$6:$D$64=$U10))) / SUM('Time Plan (Single Release)'!$Y$6:$JN$64*(IFERROR('Time Plan (Single Release)'!$I$6:$I$64*40,0))*('Time Plan (Single Release)'!$D$6:$D$64=$U10)),"")} -> 0.038841343 | AE10: =SUMIF('Time Plan (Single Release)'!D$6:D$64,Pricing!U10,'Time Plan (Single Release)'!S$6:S$64) -> 160 | AF10: =AE10/8 -> 20 | AG10: =IFERROR(AE10+(AA$4*AI10/W10),"") -> 160 | AH10: =IFERROR(AG10/8,"") -> 20 | AI10: 0 | AJ10: =AG10*W10 -> 24304
C11: {=IFERROR(INDEX('Time Plan (Single Release)'!$Y$3:$JN$3, 1, _xlfn.XMATCH(TRUE, _xlfn.BYCOL(('Time Plan (Single Release)'!$Y$6:$JN$64)*('Time Plan (Single Release)'!$B$6:$B$64=$B11), _xlfn.LAMBDA(_xlpm.col, SUM(_xlpm.col)>0)), 0, 1)),"")} | D11: {=IFERROR(INDEX('Time Plan (Single Release)'!$Y$3:$JN$3, 1, _xlfn.XMATCH(TRUE, _xlfn.BYCOL(('Time Plan (Single Release)'!$Y$6:$JN$64)*('Time Plan (Single Release)'!$B$6:$B$64=$B11), _xlfn.LAMBDA(_xlpm.col, SUM(_xlpm.col)>0)), 0,-1))+4,"")} | E11: =IFERROR(DATEDIF('Time Plan (Single Release)'!$Y$3,$D11+3,"d")/7,"") | F11: {=SUM(IFERROR(('Time Plan (Single Release)'!$U$6:$U$64*('Time Plan (Single Release)'!$B$6:$B$64=Pricing!$B11)),0))} -> 0 | G11: =$F11*0.1 -> 0 | H11: =$F11*1.1 -> 0 | I11: {=IFERROR( (SUM('Time Plan (Single Release)'!$Y$6:$JN$64*(IFERROR('Time Plan (Single Release)'!$G$6:$G$64*40,0))*('Time Plan (Single Release)'!$B$6:$B$64=Pricing!$B11)) - SUM('Time Plan (Single Release)'!$Y$6:$JN$64*(IFERROR('Time Plan (Single Release)'!$I$6:$I$64*40,0))*('Time Plan (Single Release)'!$B$6:$B$64=Pricing!$B11))) / SUM('Time Plan (Single Release)'!$Y$6:$JN$64*(IFERROR('Time Plan (Single Release)'!$G$6:$G$64*40,0))*('Time Plan (Single Release)'!$B$6:$B$64=Pricing!$B11)),"")} | J11: {=IFERROR( (SUM('Time Plan (Single Release)'!$Y$6:$JN$64*(IFERROR('Time Plan (Single Release)'!$I$6:$I$64*40,0))*('Time Plan (Single Release)'!$B$6:$B$64=Pricing!$B11)) - SUM('Time Plan (Single Release)'!$Y$6:$JN$64*(IFERROR('Time Plan (Single Release)'!$K$6:$K$64*40,0))*('Time Plan (Single Release)'!$B$6:$B$64=Pricing!$B11))) / SUM('Time Plan (Single Release)'!$Y$6:$JN$64*(IFERROR('Time Plan (Single Release)'!$I$6:$I$64*40,0))*('Time Plan (Single Release)'!$B$6:$B$64=Pricing!$B11)),"")} | M11: {=IFERROR(INDEX('Time Plan (Single Release)'!$Y$3:$JN$3, 1, _xlfn.XMATCH(TRUE, _xlfn.BYCOL(('Time Plan (Single Release)'!$Y$6:$JN$64)*('Time Plan (Single Release)'!$C$6:$C$64=$L11), _xlfn.LAMBDA(_xlpm.col, SUM(_xlpm.col)>0)), 0, 1)),"")} | N11: {=IFERROR(INDEX('Time Plan (Single Release)'!$Y$3:$JN$3, 1, _xlfn.XMATCH(TRUE, _xlfn.BYCOL(('Time Plan (Single Release)'!$Y$6:$JN$64)*('Time Plan (Single Release)'!$C$6:$C$64=$L11), _xlfn.LAMBDA(_xlpm.col, SUM(_xlpm.col)>0)), 0,-1))+4,"")} | O11: {=SUM(IFERROR(('Time Plan (Single Release)'!$U$6:$U$64*('Time Plan (Single Release)'!$C$6:$C$64=$L11)),0))} -> 0 | P11: =IFERROR(O11*0.1,"") -> 0 | Q11: =O11*1.1 -> 0 | R11: {=IFERROR( (SUM('Time Plan (Single Release)'!$Y$6:$JN$64*(IFERROR('Time Plan (Single Release)'!$G$6:$G$64*40,0))*('Time Plan (Single Release)'!$C$6:$C$64=$L11)) - SUM('Time Plan (Single Release)'!$Y$6:$JN$64*(IFERROR('Time Plan (Single Release)'!$I$6:$I$64*40,0))*('Time Plan (Single Release)'!$C$6:$C$64=$L11))) / SUM('Time Plan (Single Release)'!$Y$6:$JN$64*(IFERROR('Time Plan (Single Release)'!$G$6:$G$64*40,0))*('Time Plan (Single Release)'!$C$6:$C$64=$L11)),"")} | S11: {=IFERROR( (SUM('Time Plan (Single Release)'!$Y$6:$JN$64*(IFERROR('Time Plan (Single Release)'!$I$6:$I$64*40,0))*('Time Plan (Single Release)'!$C$6:$C$64=$L11)) - SUM('Time Plan (Single Release)'!$Y$6:$JN$64*(IFERROR('Time Plan (Single Release)'!$K$6:$K$64*40,0))*('Time Plan (Single Release)'!$C$6:$C$64=$L11))) / SUM('Time Plan (Single Release)'!$Y$6:$JN$64*(IFERROR('Time Plan (Single Release)'!$I$6:$I$64*40,0))*('Time Plan (Single Release)'!$C$6:$C$64=$L11)),"")} | U11: Lynne Sutherland | V11: {=IFERROR(_xlfn.XLOOKUP($U11,'Time Plan (Single Release)'!$D$6:$D$194,'Time Plan (Single Release)'!$E$6:$E$194&" - "&'Time Plan (Single Release)'!$F$6:$F$194),"")} -> Level 3 - Business Analyst | W11: =IFERROR(_xlfn.XLOOKUP($U11,'Time Plan (Single Release)'!$D$6:$D$64,'Time Plan (Single Release)'!$I$6:$I$64),"") -> 151.9 | X11: =IFERROR(W11*1.1,"") -> 167.09 | Y11: {=IFERROR(INDEX('Time Plan (Single Release)'!$Y$3:$JN$3, 1, _xlfn.XMATCH(TRUE, _xlfn.BYCOL(('Time Plan (Single Release)'!$Y$6:$JN$64)*('Time Plan (Single Release)'!$D$6:$D$64=$U11), _xlfn.LAMBDA(_xlpm.col, SUM(_xlpm.col)>0)), 0, 1)),"")} -> 46062 | Z11: {=IFERROR(INDEX('Time Plan (Single Release)'!$Y$3:$JN$3, 1, _xlfn.XMATCH(TRUE, _xlfn.BYCOL(('Time Plan (Single Release)'!$Y$6:$JN$64)*('Time Plan (Single Release)'!$D$6:$D$64=$U11), _xlfn.LAMBDA(_xlpm.col, SUM(_xlpm.col)>0)), 0,-1))+4,"")} -> 46164 | AA11: {=SUM(IFERROR(('Time Plan (Single Release)'!$U$6:$U$64*('Time Plan (Single Release)'!$D$6:$D$64=$U11)),0))} -> 72912 | AB11: =AA11*1.1 -> 80203.2 | AC11: {=IFERROR( (SUM('Time Plan (Single Release)'!$Y$6:$JN$64*(IFERROR('Time Plan (Single Release)'!$G$6:$G$64*40,0))*('Time Plan (Single Release)'!$D$6:$D$64=$U11)) - SUM('Time Plan (Single Release)'!$Y$6:$JN$64*(IFERROR('Time Plan (Single Release)'!$I$6:$I$64*40,0))*('Time Plan (Single Release)'!$D$6:$D$64=$U11))) / SUM('Time Plan (Single Release)'!$Y$6:$JN$64*(IFERROR('Time Plan (Single Release)'!$G$6:$G$64*40,0))*('Time Plan (Single Release)'!$D$6:$D$64=$U11)),"")} -> 0.38 | AD11: {=IFERROR( (SUM('Time Plan (Single Release)'!$Y$6:$JN$64*(IFERROR('Time Plan (Single Release)'!$I$6:$I$64*40,0))*('Time Plan (Single Release)'!$D$6:$D$64=$U11)) - SUM('Time Plan (Single Release)'!$Y$6:$JN$64*(IFERROR('Time Plan (Single Release)'!$K$6:$K$64*40,0))*('Time Plan (Single Release)'!$D$6:$D$64=$U11))) / SUM('Time Plan (Single Release)'!$Y$6:$JN$64*(IFERROR('Time Plan (Single Release)'!$I$6:$I$64*40,0))*('Time Plan (Single Release)'!$D$6:$D$64=$U11)),"")} -> 0.40750494 | AE11: =SUMIF('Time Plan (Single Release)'!D$6:D$64,Pricing!U11,'Time Plan (Single Release)'!S$6:S$64) -> 480 | AF11: =AE11/8 -> 60 | AG11: =IFERROR(AE11+(AA$4*AI11/W11),"") -> 480 | AH11: =IFERROR(AG11/8,"") -> 60 | AI11: 0 | AJ11: =AG11*W11 -> 72912
C12: {=IFERROR(INDEX('Time Plan (Single Release)'!$Y$3:$JN$3, 1, _xlfn.XMATCH(TRUE, _xlfn.BYCOL(('Time Plan (Single Release)'!$Y$6:$JN$64)*('Time Plan (Single Release)'!$B$6:$B$64=$B12), _xlfn.LAMBDA(_xlpm.col, SUM(_xlpm.col)>0)), 0, 1)),"")} | D12: {=IFERROR(INDEX('Time Plan (Single Release)'!$Y$3:$JN$3, 1, _xlfn.XMATCH(TRUE, _xlfn.BYCOL(('Time Plan (Single Release)'!$Y$6:$JN$64)*('Time Plan (Single Release)'!$B$6:$B$64=$B12), _xlfn.LAMBDA(_xlpm.col, SUM(_xlpm.col)>0)), 0,-1))+4,"")} | E12: =IFERROR(DATEDIF('Time Plan (Single Release)'!$Y$3,$D12+3,"d")/7,"") | F12: {=SUM(IFERROR(('Time Plan (Single Release)'!$U$6:$U$64*('Time Plan (Single Release)'!$B$6:$B$64=Pricing!$B12)),0))} -> 0 | G12: =$F12*0.1 -> 0 | H12: =$F12*1.1 -> 0 | I12: {=IFERROR( (SUM('Time Plan (Single Release)'!$Y$6:$JN$64*(IFERROR('Time Plan (Single Release)'!$G$6:$G$64*40,0))*('Time Plan (Single Release)'!$B$6:$B$64=Pricing!$B12)) - SUM('Time Plan (Single Release)'!$Y$6:$JN$64*(IFERROR('Time Plan (Single Release)'!$I$6:$I$64*40,0))*('Time Plan (Single Release)'!$B$6:$B$64=Pricing!$B12))) / SUM('Time Plan (Single Release)'!$Y$6:$JN$64*(IFERROR('Time Plan (Single Release)'!$G$6:$G$64*40,0))*('Time Plan (Single Release)'!$B$6:$B$64=Pricing!$B12)),"")} | J12: {=IFERROR( (SUM('Time Plan (Single Release)'!$Y$6:$JN$64*(IFERROR('Time Plan (Single Release)'!$I$6:$I$64*40,0))*('Time Plan (Single Release)'!$B$6:$B$64=Pricing!$B12)) - SUM('Time Plan (Single Release)'!$Y$6:$JN$64*(IFERROR('Time Plan (Single Release)'!$K$6:$K$64*40,0))*('Time Plan (Single Release)'!$B$6:$B$64=Pricing!$B12))) / SUM('Time Plan (Single Release)'!$Y$6:$JN$64*(IFERROR('Time Plan (Single Release)'!$I$6:$I$64*40,0))*('Time Plan (Single Release)'!$B$6:$B$64=Pricing!$B12)),"")} | M12: {=IFERROR(INDEX('Time Plan (Single Release)'!$Y$3:$JN$3, 1, _xlfn.XMATCH(TRUE, _xlfn.BYCOL(('Time Plan (Single Release)'!$Y$6:$JN$64)*('Time Plan (Single Release)'!$C$6:$C$64=$L12), _xlfn.LAMBDA(_xlpm.col, SUM(_xlpm.col)>0)), 0, 1)),"")} | N12: {=IFERROR(INDEX('Time Plan (Single Release)'!$Y$3:$JN$3, 1, _xlfn.XMATCH(TRUE, _xlfn.BYCOL(('Time Plan (Single Release)'!$Y$6:$JN$64)*('Time Plan (Single Release)'!$C$6:$C$64=$L12), _xlfn.LAMBDA(_xlpm.col, SUM(_xlpm.col)>0)), 0,-1))+4,"")} | O12: {=SUM(IFERROR(('Time Plan (Single Release)'!$U$6:$U$64*('Time Plan (Single Release)'!$C$6:$C$64=$L12)),0))} -> 0 | P12: =IFERROR(O12*0.1,"") -> 0 | Q12: =O12*1.1 -> 0 | R12: {=IFERROR( (SUM('Time Plan (Single Release)'!$Y$6:$JN$64*(IFERROR('Time Plan (Single Release)'!$G$6:$G$64*40,0))*('Time Plan (Single Release)'!$C$6:$C$64=$L12)) - SUM('Time Plan (Single Release)'!$Y$6:$JN$64*(IFERROR('Time Plan (Single Release)'!$I$6:$I$64*40,0))*('Time Plan (Single Release)'!$C$6:$C$64=$L12))) / SUM('Time Plan (Single Release)'!$Y$6:$JN$64*(IFERROR('Time Plan (Single Release)'!$G$6:$G$64*40,0))*('Time Plan (Single Release)'!$C$6:$C$64=$L12)),"")} | S12: {=IFERROR( (SUM('Time Plan (Single Release)'!$Y$6:$JN$64*(IFERROR('Time Plan (Single Release)'!$I$6:$I$64*40,0))*('Time Plan (Single Release)'!$C$6:$C$64=$L12)) - SUM('Time Plan (Single Release)'!$Y$6:$JN$64*(IFERROR('Time Plan (Single Release)'!$K$6:$K$64*40,0))*('Time Plan (Single Release)'!$C$6:$C$64=$L12))) / SUM('Time Plan (Single Release)'!$Y$6:$JN$64*(IFERROR('Time Plan (Single Release)'!$I$6:$I$64*40,0))*('Time Plan (Single Release)'!$C$6:$C$64=$L12)),"")} | U12: Mahesh Vemegal | V12: {=IFERROR(_xlfn.XLOOKUP($U12,'Time Plan (Single Release)'!$D$6:$D$194,'Time Plan (Single Release)'!$E$6:$E$194&" - "&'Time Plan (Single Release)'!$F$6:$F$194),"")} -> Level 4 - Lead ServiceNow Developer | W12: =IFERROR(_xlfn.XLOOKUP($U12,'Time Plan (Single Release)'!$D$6:$D$64,'Time Plan (Single Release)'!$I$6:$I$64),"") -> 207.4 | X12: =IFERROR(W12*1.1,"") -> 228.14 | Y12: {=IFERROR(INDEX('Time Plan (Single Release)'!$Y$3:$JN$3, 1, _xlfn.XMATCH(TRUE, _xlfn.BYCOL(('Time Plan (Single Release)'!$Y$6:$JN$64)*('Time Plan (Single Release)'!$D$6:$D$64=$U12), _xlfn.LAMBDA(_xlpm.col, SUM(_xlpm.col)>0)), 0, 1)),"")} -> 46076 | Z12: {=IFERROR(INDEX('Time Plan (Single Release)'!$Y$3:$JN$3, 1, _xlfn.XMATCH(TRUE, _xlfn.BYCOL(('Time Plan (Single Release)'!$Y$6:$JN$64)*('Time Plan (Single Release)'!$D$6:$D$64=$U12), _xlfn.LAMBDA(_xlpm.col, SUM(_xlpm.col)>0)), 0,-1))+4,"")} -> 46164 | AA12: {=SUM(IFERROR(('Time Plan (Single Release)'!$U$6:$U$64*('Time Plan (Single Release)'!$D$6:$D$64=$U12)),0))} -> 95404 | AB12: =AA12*1.1 -> 104944.4 | AC12: {=IFERROR( (SUM('Time Plan (Single Release)'!$Y$6:$JN$64*(IFERROR('Time Plan (Single Release)'!$G$6:$G$64*40,0))*('Time Plan (Single Release)'!$D$6:$D$64=$U12)) - SUM('Time Plan (Single Release)'!$Y$6:$JN$64*(IFERROR('Time Plan (Single Release)'!$I$6:$I$64*40,0))*('Time Plan (Single Release)'!$D$6:$D$64=$U12))) / SUM('Time Plan (Single Release)'!$Y$6:$JN$64*(IFERROR('Time Plan (Single Release)'!$G$6:$G$64*40,0))*('Time Plan (Single Release)'!$D$6:$D$64=$U12)),"")} -> 0.32 | AD12: {=IFERROR( (SUM('Time Plan (Single Release)'!$Y$6:$JN$64*(IFERROR('Time Plan (Single Release)'!$I$6:$I$64*40,0))*('Time Plan (Single Release)'!$D$6:$D$64=$U12)) - SUM('Time Plan (Single Release)'!$Y$6:$JN$64*(IFERROR('Time Plan (Single Release)'!$K$6:$K$64*40,0))*('Time Plan (Single Release)'!$D$6:$D$64=$U12))) / SUM('Time Plan (Single Release)'!$Y$6:$JN$64*(IFERROR('Time Plan (Single Release)'!$I$6:$I$64*40,0))*('Time Plan (Single Release)'!$D$6:$D$64=$U12)),"")} -> 0.17569913 | AE12: =SUMIF('Time Plan (Single Release)'!D$6:D$64,Pricing!U12,'Time Plan (Single Release)'!S$6:S$64) -> 460 | AF12: =AE12/8 -> 57.5 | AG12: =IFERROR(AE12+(AA$8*AI12/W12),"") -> 460 | AH12: =IFERROR(AG12/8,"") -> 57.5
