Workbook
Name CompanyFairToggle: Summary!$D$61
Name CompanyGoodToggle: Summary!$D$60
Name CompanyRiskToggle: Summary!$D$62
Name DAFFFairToggle: 'DAFF VAT Summary'!$M$3
Name DAFFGoodToggle: 'DAFF VAT Summary'!$L$3
Name DAFFRiskToggle: 'DAFF VAT Summary'!$N$3
Name DISRFairToggle: 'DISR VAT Summary'!$M$3
Name DISRGoodToggle: 'DISR VAT Summary'!$L$3
Name DISRRiskToggle: 'DISR VAT Summary'!$N$3
Name EmergingFairToggle: 'EMERGING VAT Summary'!$M$3
Name EmergingGoodToggle: 'EMERGING VAT Summary'!$L$3
Name EmergingRiskToggle: 'EMERGING VAT Summary'!$N$3
Name FairToggle: 'COMPANY Spread'!$E$64
Name GoodToggle: 'COMPANY Spread'!$D$64
Name GROWTHFairToggle: 'GROWTH VAT Summary'!$M$3
Name GROWTHGoodToggle: 'GROWTH VAT Summary'!$L$3
Name GROWTHRiskToggle: 'GROWTH VAT Summary'!$N$3
Name QBlockGMC: _xlfn.LET(_xlpm.top,'Q Spread Calculation'!$A$4, OFFSET(_xlpm.top, -1, 0, ROWS(_xlfn.ANCHORARRAY(_xlpm.top))+1, COLUMNS(_xlfn.ANCHORARRAY(_xlpm.top))+12))
Name QBlockRev: _xlfn.LET(_xlpm.top,'Q Spread Calculation'!$S$4, OFFSET(_xlpm.top, -1, 0, ROWS(_xlfn.ANCHORARRAY(_xlpm.top))+1, COLUMNS(_xlfn.ANCHORARRAY(_xlpm.top))+12))
Name RiskToggle: 'COMPANY Spread'!$F$64
Name SAUFairToggle: 'DISR VAT Summary'!$M$3
Name SAUFairToggle: 'EMERGING VAT Summary'!$M$3
Name SAUFairToggle: 'SAU VAT Summary'!$M$3
Name SAUGoodToggle: 'DISR VAT Summary'!$L$3
Name SAUGoodToggle: 'EMERGING VAT Summary'!$L$3
Name SAUGoodToggle: 'SAU VAT Summary'!$L$3
Name SAURiskToggle: 'DISR VAT Summary'!$N$3
Name SAURiskToggle: 'EMERGING VAT Summary'!$N$3
Name SAURiskToggle: 'SAU VAT Summary'!$N$3
Name Slicer_Status: #N/A
Name Slicer_VAT: #N/A
Name Slicer_VAT1: #N/A
Name VATSelector: 'COMPANY Spread'!$B$66
Name VICFairToggle: 'VIC VAT Summary'!$M$3
Name VICGoodToggle: 'VIC VAT Summary'!$L$3
Name VICRiskToggle: 'VIC VAT Summary'!$N$3

Sheet Summary
B2: SALES DASHBOARD
C5: TOTAL | D5: Revenue Target | H5: Revenue
D6: OK | E6: Good | F6: Great | G6: Amazing | H6: Earned to Date | J6: Revenue | K6: GM % | L6: Current Jobs @ Completion | N6: Revenue | O6: GM % | P6: Plus Selected | R6: Plus Shortlisted (DVF) | T6: Plus Submitted (DF)
D7: ='FY2526 VAT Financial KPIs'!E4 -> 24648402 | E7: ='FY2526 VAT Financial KPIs'!F4 -> 33946753 | F7: ='FY2526 VAT Financial KPIs'!G4 -> 42979437 | G7: ='FY2526 VAT Financial KPIs'!H4 -> 46362500 | H7: =Job_Status[[#Totals],[Actual]] -> 14133437 | I7: =H7/E7 -> 0.41634135 | L7: =Job_Status[[#Totals],[Forecasted Revenue]] -> 20744604 | M7: =L7/E7 -> 0.61109242 | P7: =IF(CompanyGoodToggle=TRUE,SUMIFS(OppSpreadData[FY25/26],OppSpreadData[Open Opps Phase],"5.S - Selected",OppSpreadData[OppsStatus],"Good"),0)+IF(CompanyFairToggle=TRUE,SUMIFS(OppSpreadData[FY25/26],OppSpreadData[Open Opps Phase],"5.S - Selected",OppSpreadData[OppsStatus],"Fair"),0)+IF(CompanyRiskToggle=TRUE,SUMIFS(OppSpreadData[FY25/26],OppSpreadData[Open Opps Phase],"5.S - Selected",OppSpreadData[OppsStatus],"Risk"),0)+L7 -> 20744604 | Q7: =P7/E7 -> 0.61109242 | R7: =IF(CompanyGoodToggle=TRUE,SUMIFS(OppSpreadData[FY25/26],OppSpreadData[Open Opps Phase],"4.DVF - Shortlisted",OppSpreadData[OppsStatus],"Good"),0)+IF(CompanyFairToggle=TRUE,SUMIFS(OppSpreadData[FY25/26],OppSpreadData[Open Opps Phase],"4.DVF - Shortlisted",OppSpreadData[OppsStatus],"Fair"),0)+IF(CompanyRiskToggle=TRUE,SUMIFS(OppSpreadData[FY25/26],OppSpreadData[Open Opps Phase],"4.DVF - Shortlisted",OppSpreadData[OppsStatus],"Risk"),0)+P7 -> 25242354 | S7: =R7/E7 -> 0.74358669 | T7: =IF(CompanyGoodToggle=TRUE,SUMIFS(OppSpreadData[FY25/26],OppSpreadData[Open Opps Phase],"3.DF - Submitted",OppSpreadData[OppsStatus],"Good"),0)+IF(CompanyFairToggle=TRUE,SUMIFS(OppSpreadData[FY25/26],OppSpreadData[Open Opps Phase],"3.DF - Submitted",OppSpreadData[OppsStatus],"Fair"),0)+IF(CompanyRiskToggle=TRUE,SUMIFS(OppSpreadData[FY25/26],OppSpreadData[Open Opps Phase],"3.DF - Submitted",OppSpreadData[OppsStatus],"Risk"),0)+R7 -> 25242354 | U7: =T7/E7 -> 0.74358669
D8: Gross Margin Contribution Target | H8: GM Contribution
C9: VAT | D9: OK | E9: Good | F9: Great | G9: Amazing | H9: Earned to Date | J9: Revenue | K9: GM % | L9: Current Jobs @ Completion | N9: Revenue | O9: GM % | P9: Plus Selected | R9: Plus Shortlisted (DVF) | T9: Plus Submitted (DF)
C10: DAFF | D10: ='FY2526 VAT Financial KPIs'!E7 -> 1800000 | E10: ='FY2526 VAT Financial KPIs'!F7 -> 2250000 | F10: ='FY2526 VAT Financial KPIs'!G7 -> 2700000 | G10: ='FY2526 VAT Financial KPIs'!H7 -> 3150000 | H10: =SUMIF(Job_Status[VAT],Summary!C10,Job_Status[To Date Gross Profit]) -> 799904.52 | I10: =H10/E10 -> 0.35551312 | J10: =SUMIF(Job_Status[VAT],Summary!C10,Job_Status[Actual]) -> 3157524.8 | K10: =IFERROR(H10/J10,"") -> 0.25333278 | L10: =SUMIF(Job_Status[VAT],Summary!C10,Job_Status[GP at completion]) -> 1019174.6 | M10: =L10/E10 -> 0.45296649 | N10: =SUMIF(Job_Status[VAT],Summary!C10,Job_Status[Forecasted Revenue]) -> 4480245.8 | O10: =L10/N10 -> 0.22748185 | P10: =IF(CompanyGoodToggle=TRUE,SUMIFS(TotalGMContribution[FY25/26],TotalGMContribution[Opps Status],"Good",TotalGMContribution[Open Opps Phase],"5.S - Selected",TotalGMContribution[VAT],Summary!$C10),0)+IF(CompanyFairToggle=TRUE,SUMIFS(TotalGMContribution[FY25/26],TotalGMContribution[Opps Status],"Fair",TotalGMContribution[Open Opps Phase],"5.S - Selected",TotalGMContribution[VAT],Summary!$C10),0)+IF(CompanyRiskToggle=TRUE,SUMIFS(TotalGMContribution[FY25/26],TotalGMContribution[Opps Status],"Risk",TotalGMContribution[Open Opps Phase],"5.S - Selected",TotalGMContribution[VAT],Summary!$C10),0)+L10 -> 1019174.6 | Q10: =P10/E10 -> 0.45296649 | R10: =IF(CompanyGoodToggle=TRUE,SUMIFS(TotalGMContribution[FY25/26],TotalGMContribution[Opps Status],"Good",TotalGMContribution[Open Opps Phase],"4.DVF - Shortlisted",TotalGMContribution[VAT],Summary!$C10),0)+IF(CompanyFairToggle=TRUE,SUMIFS(TotalGMContribution[FY25/26],TotalGMContribution[Opps Status],"Fair",TotalGMContribution[Open Opps Phase],"4.DVF - Shortlisted",TotalGMContribution[VAT],Summary!$C10),0)+IF(CompanyRiskToggle=TRUE,SUMIFS(TotalGMContribution[FY25/26],TotalGMContribution[Opps Status],"Risk",TotalGMContribution[Open Opps Phase],"4.DVF - Shortlisted",TotalGMContribution[VAT],Summary!$C10),0)+P10 -> 1019174.6 | S10: =R10/E10 -> 0.45296649 | T10: =IF(CompanyGoodToggle=TRUE,SUMIFS(TotalGMContribution[FY25/26],TotalGMContribution[Opps Status],"Good",TotalGMContribution[Open Opps Phase],"3.DF - Submitted",TotalGMContribution[VAT],Summary!$C10),0)+IF(CompanyFairToggle=TRUE,SUMIFS(TotalGMContribution[FY25/26],TotalGMContribution[Opps Status],"Fair",TotalGMContribution[Open Opps Phase],"3.DF - Submitted",TotalGMContribution[VAT],Summary!$C10),0)+IF(CompanyRiskToggle=TRUE,SUMIFS(TotalGMContribution[FY25/26],TotalGMContribution[Opps Status],"Risk",TotalGMContribution[Open Opps Phase],"3.DF - Submitted",TotalGMContribution[VAT],Summary!$C10),0)+R10 -> 1019174.6 | U10: =T10/E10 -> 0.45296649
C11: SAU | D11: ='FY2526 VAT Financial KPIs'!E15 -> 900000 | E11: ='FY2526 VAT Financial KPIs'!F15 -> 1350000 | F11: ='FY2526 VAT Financial KPIs'!G15 -> 1800000 | G11: ='FY2526 VAT Financial KPIs'!H15 -> 2250000 | H11: =SUMIF(Job_Status[VAT],Summary!C11,Job_Status[To Date Gross Profit]) -> 371345.48 | I11: =H11/E11 -> 0.27507073 | J11: =SUMIF(Job_Status[VAT],Summary!C11,Job_Status[Actual]) -> 2815849.9 | K11: =IFERROR(H11/J11,"") -> 0.13187687 | L11: =SUMIF(Job_Status[VAT],Summary!C11,Job_Status[GP at completion]) -> 587063.76 | M11: =L11/E11 -> 0.43486204 | N11: =SUMIF(Job_Status[VAT],Summary!C11,Job_Status[Forecasted Revenue]) -> 4568637.9 | O11: =L11/N11 -> 0.12849864 | P11: =IF(CompanyGoodToggle=TRUE,SUMIFS(TotalGMContribution[FY25/26],TotalGMContribution[Opps Status],"Good",TotalGMContribution[Open Opps Phase],"5.S - Selected",TotalGMContribution[VAT],Summary!$C11),0)+IF(CompanyFairToggle=TRUE,SUMIFS(TotalGMContribution[FY25/26],TotalGMContribution[Opps Status],"Fair",TotalGMContribution[Open Opps Phase],"5.S - Selected",TotalGMContribution[VAT],Summary!$C11),0)+IF(CompanyRiskToggle=TRUE,SUMIFS(TotalGMContribution[FY25/26],TotalGMContribution[Opps Status],"Risk",TotalGMContribution[Open Opps Phase],"5.S - Selected",TotalGMContribution[VAT],Summary!$C11),0)+L11 -> 587063.76 | Q11: =P11/E11 -> 0.43486204 | R11: =IF(CompanyGoodToggle=TRUE,SUMIFS(TotalGMContribution[FY25/26],TotalGMContribution[Opps Status],"Good",TotalGMContribution[Open Opps Phase],"4.DVF - Shortlisted",TotalGMContribution[VAT],Summary!$C11),0)+IF(CompanyFairToggle=TRUE,SUMIFS(TotalGMContribution[FY25/26],TotalGMContribution[Opps Status],"Fair",TotalGMContribution[Open Opps Phase],"4.DVF - Shortlisted",TotalGMContribution[VAT],Summary!$C11),0)+IF(CompanyRiskToggle=TRUE,SUMIFS(TotalGMContribution[FY25/26],TotalGMContribution[Opps Status],"Risk",TotalGMContribution[Open Opps Phase],"4.DVF - Shortlisted",TotalGMContribution[VAT],Summary!$C11),0)+P11 -> 618169.2 | S11: =R11/E11 -> 0.45790311 | T11: =IF(CompanyGoodToggle=TRUE,SUMIFS(TotalGMContribution[FY25/26],TotalGMContribution[Opps Status],"Good",TotalGMContribution[Open Opps Phase],"3.DF - Submitted",TotalGMContribution[VAT],Summary!$C11),0)+IF(CompanyFairToggle=TRUE,SUMIFS(TotalGMContribution[FY25/26],TotalGMContribution[Opps Status],"Fair",TotalGMContribution[Open Opps Phase],"3.DF - Submitted",TotalGMContribution[VAT],Summary!$C11),0)+IF(CompanyRiskToggle=TRUE,SUMIFS(TotalGMContribution[FY25/26],TotalGMContribution[Opps Status],"Risk",TotalGMContribution[Open Opps Phase],"3.DF - Submitted",TotalGMContribution[VAT],Summary!$C11),0)+R11 -> 618169.2 | U11: =T11/E11 -> 0.45790311
C12: VIC Gov | D12: ='FY2526 VAT Financial KPIs'!E11 -> 1800000 | E12: ='FY2526 VAT Financial KPIs'!F11 -> 2250000 | F12: ='FY2526 VAT Financial KPIs'!G11 -> 2700000 | G12: ='FY2526 VAT Financial KPIs'!H11 -> 3150000 | H12: =SUMIF(Job_Status[VAT],Summary!C12,Job_Status[To Date Gross Profit]) -> 1008147.9 | I12: =H12/E12 -> 0.44806574 | J12: =SUMIF(Job_Status[VAT],Summary!C12,Job_Status[Actual]) -> 3194123.7 | K12: =IFERROR(H12/J12,"") -> 0.31562582 | L12: =SUMIF(Job_Status[VAT],Summary!C12,Job_Status[GP at completion]) -> 1026935 | M12: =L12/E12 -> 0.45641557 | N12: =SUMIF(Job_Status[VAT],Summary!C12,Job_Status[Forecasted Revenue]) -> 3253993.7 | O12: =L12/N12 -> 0.3155922 | P12: =IF(CompanyGoodToggle=TRUE,SUMIFS(TotalGMContribution[FY25/26],TotalGMContribution[Opps Status],"Good",TotalGMContribution[Open Opps Phase],"5.S - Selected",TotalGMContribution[VAT],Summary!$C12),0)+IF(CompanyFairToggle=TRUE,SUMIFS(TotalGMContribution[FY25/26],TotalGMContribution[Opps Status],"Fair",TotalGMContribution[Open Opps Phase],"5.S - Selected",TotalGMContribution[VAT],Summary!$C12),0)+IF(CompanyRiskToggle=TRUE,SUMIFS(TotalGMContribution[FY25/26],TotalGMContribution[Opps Status],"Risk",TotalGMContribution[Open Opps Phase],"5.S - Selected",TotalGMContribution[VAT],Summary!$C12),0)+L12 -> 1026935 | Q12: =P12/E12 -> 0.45641557 | R12: =IF(CompanyGoodToggle=TRUE,SUMIFS(TotalGMContribution[FY25/26],TotalGMContribution[Opps Status],"Good",TotalGMContribution[Open Opps Phase],"4.DVF - Shortlisted",TotalGMContribution[VAT],Summary!$C12),0)+IF(CompanyFairToggle=TRUE,SUMIFS(TotalGMContribution[FY25/26],TotalGMContribution[Opps Status],"Fair",TotalGMContribution[Open Opps Phase],"4.DVF - Shortlisted",TotalGMContribution[VAT],Summary!$C12),0)+IF(CompanyRiskToggle=TRUE,SUMIFS(TotalGMContribution[FY25/26],TotalGMContribution[Opps Status],"Risk",TotalGMContribution[Open Opps Phase],"4.DVF - Shortlisted",TotalGMContribution[VAT],Summary!$C12),0)+P12 -> 1026935 | S12: =R12/E12 -> 0.45641557 | T12: =IF(CompanyGoodToggle=TRUE,SUMIFS(TotalGMContribution[FY25/26],TotalGMContribution[Opps Status],"Good",TotalGMContribution[Open Opps Phase],"3.DF - Submitted",TotalGMContribution[VAT],Summary!$C12),0)+IF(CompanyFairToggle=TRUE,SUMIFS(TotalGMContribution[FY25/26],TotalGMContribution[Opps Status],"Fair",TotalGMContribution[Open Opps Phase],"3.DF - Submitted",TotalGMContribution[VAT],Summary!$C12),0)+IF(CompanyRiskToggle=TRUE,SUMIFS(TotalGMContribution[FY25/26],TotalGMContribution[Opps Status],"Risk",TotalGMContribution[Open Opps Phase],"3.DF - Submitted",TotalGMContribution[VAT],Summary!$C12),0)+R12 -> 1026935 | U12: =T12/E12 -> 0.45641557
C13: DISR | D13: ='FY2526 VAT Financial KPIs'!E28 -> 690000 | E13: ='FY2526 VAT Financial KPIs'!F28 -> 1200000 | F13: ='FY2526 VAT Financial KPIs'!G28 -> 1500000 | G13: ='FY2526 VAT Financial KPIs'!H28 -> 2100000 | H13: =SUMIF(Job_Status[VAT],Summary!C13,Job_Status[To Date Gross Profit]) -> 480114.13 | I13: =H13/E13 -> 0.40009511 | J13: =SUMIF(Job_Status[VAT],Summary!C13,Job_Status[Actual]) -> 1728891.5 | K13: =IFERROR(H13/J13,"") -> 0.27770055 | L13: =SUMIF(Job_Status[VAT],Summary!C13,Job_Status[GP at completion]) -> 1217245.1 | M13: =L13/E13 -> 1.0143709 | N13: =SUMIF(Job_Status[VAT],Summary!C13,Job_Status[Forecasted Revenue]) -> 4359363.5 | O13: =L13/N13 -> 0.27922543 | P13: =IF(CompanyGoodToggle=TRUE,SUMIFS(TotalGMContribution[FY25/26],TotalGMContribution[Opps Status],"Good",TotalGMContribution[Open Opps Phase],"5.S - Selected",TotalGMContribution[VAT],Summary!$C13),0)+IF(CompanyFairToggle=TRUE,SUMIFS(TotalGMContribution[FY25/26],TotalGMContribution[Opps Status],"Fair",TotalGMContribution[Open Opps Phase],"5.S - Selected",TotalGMContribution[VAT],Summary!$C13),0)+IF(CompanyRiskToggle=TRUE,SUMIFS(TotalGMContribution[FY25/26],TotalGMContribution[Opps Status],"Risk",TotalGMContribution[Open Opps Phase],"5.S - Selected",TotalGMContribution[VAT],Summary!$C13),0)+L13 -> 1217245.1 | Q13: =P13/E13 -> 1.0143709 | R13: =IF(CompanyGoodToggle=TRUE,SUMIFS(TotalGMContribution[FY25/26],TotalGMContribution[Opps Status],"Good",TotalGMContribution[Open Opps Phase],"4.DVF - Shortlisted",TotalGMContribution[VAT],Summary!$C13),0)+IF(CompanyFairToggle=TRUE,SUMIFS(TotalGMContribution[FY25/26],TotalGMContribution[Opps Status],"Fair",TotalGMContribution[Open Opps Phase],"4.DVF - Shortlisted",TotalGMContribution[VAT],Summary!$C13),0)+IF(CompanyRiskToggle=TRUE,SUMIFS(TotalGMContribution[FY25/26],TotalGMContribution[Opps Status],"Risk",TotalGMContribution[Open Opps Phase],"4.DVF - Shortlisted",TotalGMContribution[VAT],Summary!$C13),0)+P13 -> 1217245.1 | S13: =R13/E13 -> 1.0143709 | T13: =IF(CompanyGoodToggle=TRUE,SUMIFS(TotalGMContribution[FY25/26],TotalGMContribution[Opps Status],"Good",TotalGMContribution[Open Opps Phase],"3.DF - Submitted",TotalGMContribution[VAT],Summary!$C13),0)+IF(CompanyFairToggle=TRUE,SUMIFS(TotalGMContribution[FY25/26],TotalGMContribution[Opps Status],"Fair",TotalGMContribution[Open Opps Phase],"3.DF - Submitted",TotalGMContribution[VAT],Summary!$C13),0)+IF(CompanyRiskToggle=TRUE,SUMIFS(TotalGMContribution[FY25/26],TotalGMContribution[Opps Status],"Risk",TotalGMContribution[Open Opps Phase],"3.DF - Submitted",TotalGMContribution[VAT],Summary!$C13),0)+R13 -> 1217245.1 | U13: =T13/E13 -> 1.0143709
C14: Emerging | D14: ='FY2526 VAT Financial KPIs'!E23 -> 540000 | E14: ='FY2526 VAT Financial KPIs'!F23 -> 880000 | F14: ='FY2526 VAT Financial KPIs'!G23 -> 1100000 | G14: ='FY2526 VAT Financial KPIs'!H23 -> 1375000 | H14: =SUMIF(Job_Status[VAT],Summary!C14,Job_Status[To Date Gross Profit]) -> 336887.66 | I14: =H14/E14 -> 0.38282689 | J14: =SUMIF(Job_Status[VAT],Summary!C14,Job_Status[Actual]) -> 820317.05 | K14: =IFERROR(H14/J14,"") -> 0.41067982 | L14: =SUMIF(Job_Status[VAT],Summary!C14,Job_Status[GP at completion]) -> 341191.66 | M14: =L14/E14 -> 0.3877178 | N14: =SUMIF(Job_Status[VAT],Summary!C14,Job_Status[Forecasted Revenue]) -> 955549.05 | O14: =L14/N14 -> 0.35706347 | P14: =IF(CompanyGoodToggle=TRUE,SUMIFS(TotalGMContribution[FY25/26],TotalGMContribution[Opps Status],"Good",TotalGMContribution[Open Opps Phase],"5.S - Selected",TotalGMContribution[VAT],Summary!$C14),0)+IF(CompanyFairToggle=TRUE,SUMIFS(TotalGMContribution[FY25/26],TotalGMContribution[Opps Status],"Fair",TotalGMContribution[Open Opps Phase],"5.S - Selected",TotalGMContribution[VAT],Summary!$C14),0)+IF(CompanyRiskToggle=TRUE,SUMIFS(TotalGMContribution[FY25/26],TotalGMContribution[Opps Status],"Risk",TotalGMContribution[Open Opps Phase],"5.S - Selected",TotalGMContribution[VAT],Summary!$C14),0)+L14 -> 341191.66 | Q14: =P14/E14 -> 0.3877178 | R14: =IF(CompanyGoodToggle=TRUE,SUMIFS(TotalGMContribution[FY25/26],TotalGMContribution[Opps Status],"Good",TotalGMContribution[Open Opps Phase],"4.DVF - Shortlisted",TotalGMContribution[VAT],Summary!$C14),0)+IF(CompanyFairToggle=TRUE,SUMIFS(TotalGMContribution[FY25/26],TotalGMContribution[Opps Status],"Fair",TotalGMContribution[Open Opps Phase],"4.DVF - Shortlisted",TotalGMContribution[VAT],Summary!$C14),0)+IF(CompanyRiskToggle=TRUE,SUMIFS(TotalGMContribution[FY25/26],TotalGMContribution[Opps Status],"Risk",TotalGMContribution[Open Opps Phase],"4.DVF - Shortlisted",TotalGMContribution[VAT],Summary!$C14),0)+P14 -> 341191.66 | S14: =R14/E14 -> 0.3877178 | T14: =IF(CompanyGoodToggle=TRUE,SUMIFS(TotalGMContribution[FY25/26],TotalGMContribution[Opps Status],"Good",TotalGMContribution[Open Opps Phase],"3.DF - Submitted",TotalGMContribution[VAT],Summary!$C14),0)+IF(CompanyFairToggle=TRUE,SUMIFS(TotalGMContribution[FY25/26],TotalGMContribution[Opps Status],"Fair",TotalGMContribution[Open Opps Phase],"3.DF - Submitted",TotalGMContribution[VAT],Summary!$C14),0)+IF(CompanyRiskToggle=TRUE,SUMIFS(TotalGMContribution[FY25/26],TotalGMContribution[Opps Status],"Risk",TotalGMContribution[Open Opps Phase],"3.DF - Submitted",TotalGMContribution[VAT],Summary!$C14),0)+R14 -> 341191.66 | U14: =T14/E14 -> 0.3877178
C15: GROWTH | D15: ='FY2526 VAT Financial KPIs'!E19 -> 1350000 | E15: ='FY2526 VAT Financial KPIs'!F19 -> 2200000 | F15: ='FY2526 VAT Financial KPIs'!G19 -> 3300000 | G15: ='FY2526 VAT Financial KPIs'!H19 -> 4400000 | H15: =SUMIF(Job_Status[VAT],Summary!C15,Job_Status[To Date Gross Profit]) -> 1322337.3 | I15: =H15/E15 -> 0.60106241 | J15: =SUMIF(Job_Status[VAT],Summary!C15,Job_Status[Actual]) -> 2416730 | K15: =IFERROR(H15/J15,"") -> 0.54715972 | L15: =SUMIF(Job_Status[VAT],Summary!C15,Job_Status[GP at completion]) -> 1275502.3 | M15: =L15/E15 -> 0.57977379 | N15: =SUMIF(Job_Status[VAT],Summary!C15,Job_Status[Forecasted Revenue]) -> 3126813.6 | O15: =L15/N15 -> 0.40792401 | P15: =IF(CompanyGoodToggle=TRUE,SUMIFS(TotalGMContribution[FY25/26],TotalGMContribution[Opps Status],"Good",TotalGMContribution[Open Opps Phase],"5.S - Selected",TotalGMContribution[VAT],Summary!$C15),0)+IF(CompanyFairToggle=TRUE,SUMIFS(TotalGMContribution[FY25/26],TotalGMContribution[Opps Status],"Fair",TotalGMContribution[Open Opps Phase],"5.S - Selected",TotalGMContribution[VAT],Summary!$C15),0)+IF(CompanyRiskToggle=TRUE,SUMIFS(TotalGMContribution[FY25/26],TotalGMContribution[Opps Status],"Risk",TotalGMContribution[Open Opps Phase],"5.S - Selected",TotalGMContribution[VAT],Summary!$C15),0)+L15 -> 1275502.3 | Q15: =P15/E15 -> 0.57977379 | R15: =IF(CompanyGoodToggle=TRUE,SUMIFS(TotalGMContribution[FY25/26],TotalGMContribution[Opps Status],"Good",TotalGMContribution[Open Opps Phase],"4.DVF - Shortlisted",TotalGMContribution[VAT],Summary!$C15),0)+IF(CompanyFairToggle=TRUE,SUMIFS(TotalGMContribution[FY25/26],TotalGMContribution[Opps Status],"Fair",TotalGMContribution[Open Opps Phase],"4.DVF - Shortlisted",TotalGMContribution[VAT],Summary!$C15),0)+IF(CompanyRiskToggle=TRUE,SUMIFS(TotalGMContribution[FY25/26],TotalGMContribution[Opps Status],"Risk",TotalGMContribution[Open Opps Phase],"4.DVF - Shortlisted",TotalGMContribution[VAT],Summary!$C15),0)+P15 -> 3451376.7 | S15: =R15/E15 -> 1.5688076 | T15: =IF(CompanyGoodToggle=TRUE,SUMIFS(TotalGMContribution[FY25/26],TotalGMContribution[Opps Status],"Good",TotalGMContribution[Open Opps Phase],"3.DF - Submitted",TotalGMContribution[VAT],Summary!$C15),0)+IF(CompanyFairToggle=TRUE,SUMIFS(TotalGMContribution[FY25/26],TotalGMContribution[Opps Status],"Fair",TotalGMContribution[Open Opps Phase],"3.DF - Submitted",TotalGMContribution[VAT],Summary!$C15),0)+IF(CompanyRiskToggle=TRUE,SUMIFS(TotalGMContribution[FY25/26],TotalGMContribution[Opps Status],"Risk",TotalGMContribution[Open Opps Phase],"3.DF - Submitted",TotalGMContribution[VAT],Summary!$C15),0)+R15 -> 3451376.7 | U15: =T15/E15 -> 1.5688076
C16: TOTAL | D16: =SUM(D10:D15) -> 7080000 | E16: =SUM(E10:E15) -> 10130000 | F16: =SUM(F10:F15) -> 13100000 | G16: =SUM(G10:G15) -> 16425000 | H16: =SUM(H10:H15) -> 4318737 | I16: =H16/E16 -> 0.42633139 | J16: =SUM(J10:J15) -> 14133437 | K16: =H16/J16 -> 0.30556877 | L16: =SUM(L10:L15) -> 5467112.5 | M16: =L16/E16 -> 0.53969521 | N16: =SUM(N10:N15) -> 20744604 | O16: =L16/N16 -> 0.26354384 | P16: =SUM(P10:P15) -> 5467112.5 | Q16: =P16/E16 -> 0.53969521 | R16: =SUM(R10:R15) -> 7674092.4 | S16: =R16/E16 -> 0.75756094 | T16: =SUM(T10:T15) -> 7674092.4 | U16: =T16/E16 -> 0.75756094
C17: GM% | D17: =D16/D7 -> 0.28723971 | E17: =E16/E7 -> 0.29840851 | F17: =F16/F7 -> 0.30479692 | G17: =G16/G7 -> 0.35427339 | H17: =H16/H7 -> 0.30556877 | L17: =L16/L7 -> 0.26354384 | P17: =P16/P7 -> 0.26354384 | R17: =R16/R7 -> 0.30401651 | T17: =T16/T7 -> 0.30401651
H19: GM Contribution Earned | L19: GM Contribution @ Completion
G20: WORK TYPE | H20: Earned to Date | I20: GM % | J20: Revenue | K20: GM % | L20: Current Jobs @ Completion | M20: GM % | N20: Revenue | O20: GM % | P20: Plus Selected | Q20: GM % | R20: Plus Dev. Forecast (DVF) | S20: GM % | T20: Plus Defined (DF) | U20: GM % | Z20: Path | AA20: sites/RGSales/Shared Documents/General/1.Open Opportunities
G21: Advisory | H21: =SUMIF(Job_Status[Work Type],G21,Job_Status[To Date Gross Profit]) -> 1552171.7 | I21: =H21/SUMIFS(Job_Status[Actual],Job_Status[Work Type],Summary!G21) -> 0.54779326 | J21: =SUMIF(Job_Status[Work Type],Summary!G21,Job_Status[Actual]) -> 2833499 | K21: =IFERROR(H21/J21,"") -> 0.54779326 | L21: =SUMIF(Job_Status[Work Type],G21,Job_Status[GP at completion]) -> 1454981.7 | M21: =L21/SUMIFS(Job_Status[Forecasted Revenue],Job_Status[Work Type],Summary!G21) -> 0.53173149 | N21: =SUMIF(Job_Status[Work Type],G21,Job_Status[Forecasted Revenue]) -> 2736309 | O21: =L21/N21 -> 0.53173149 | P21: =IF(CompanyGoodToggle=TRUE,SUMIFS(TotalGMContribution[FY25/26],TotalGMContribution[Work Type],Summary!$G21,TotalGMContribution[Open Opps Phase],"5.S - Selected",TotalGMContribution[Opps Status],"Good"),0)+IF(CompanyFairToggle=TRUE,SUMIFS(TotalGMContribution[FY25/26],TotalGMContribution[Work Type],Summary!$G21,TotalGMContribution[Open Opps Phase],"5.S - Selected",TotalGMContribution[Opps Status],"Fair"),0)+IF(CompanyRiskToggle=TRUE,SUMIFS(TotalGMContribution[FY25/26],TotalGMContribution[Work Type],Summary!$G21,TotalGMContribution[Open Opps Phase],"5.S - Selected",TotalGMContribution[Opps Status],"Risk"),0)+L21 -> 1454981.7 | Q21: {=(SUMPRODUCT(Table_query[Value $ ex GST]*Table_query[Margin]*(Table_query[Work Type]=G21)*(Table_query[Phase]="5.S - Selected")*(Table_query[Path]="sites/RGSales/Shared Documents/General/1.Open Opportunities"))+L21)/(N21+SUMIFS(Table_query[Value $ ex GST],Table_query[Work Type],G21,Table_query[Phase],"5.S - Selected",Table_query[Path],"sites/RGSales/Shared Documents/General/1.Open Opportunities"))} -> 0.53173149 | R21: =IF(CompanyGoodToggle=TRUE,SUMIFS(TotalGMContribution[FY25/26],TotalGMContribution[Work Type],Summary!$G21,TotalGMContribution[Open Opps Phase],"4.DVF - Shortlisted",TotalGMContribution[Opps Status],"Good"),0)+IF(CompanyFairToggle=TRUE,SUMIFS(TotalGMContribution[FY25/26],TotalGMContribution[Work Type],Summary!$G21,TotalGMContribution[Open Opps Phase],"4.DVF - Shortlisted",TotalGMContribution[Opps Status],"Fair"),0)+IF(CompanyRiskToggle=TRUE,SUMIFS(TotalGMContribution[FY25/26],TotalGMContribution[Work Type],Summary!$G21,TotalGMContribution[Open Opps Phase],"4.DVF - Shortlisted",TotalGMContribution[Opps Status],"Risk"),0)+P21 -> 1454981.7 | S21: =(R21)/(N21+SUMIFS(Table_query[Value $ ex GST],Table_query[Work Type],G21,Table_query[Phase],"5.S - Selected",Table_query[Path],"sites/RGSales/Shared Documents/General/1.Open Opportunities")+SUMIFS(Table_query[Value $ ex GST],Table_query[Work Type],G21,Table_query[Phase],"3.DF - Submitted",Table_query[Path],"sites/RGSales/Shared Documents/General/1.Open Opportunities")) -> 0.53173149 | T21: =IF(CompanyGoodToggle=TRUE,SUMIFS(TotalGMContribution[FY25/26],TotalGMContribution[Work Type],Summary!$G21,TotalGMContribution[Open Opps Phase],"3.DF - Submitted",TotalGMContribution[Opps Status],"Good"),0)+IF(CompanyFairToggle=TRUE,SUMIFS(TotalGMContribution[FY25/26],TotalGMContribution[Work Type],Summary!$G21,TotalGMContribution[Open Opps Phase],"3.DF - Submitted",TotalGMContribution[Opps Status],"Fair"),0)+IF(CompanyRiskToggle=TRUE,SUMIFS(TotalGMContribution[FY25/26],TotalGMContribution[Work Type],Summary!$G21,TotalGMContribution[Open Opps Phase],"3.DF - Submitted",TotalGMContribution[Opps Status],"Risk"),0)+R21 -> 1454981.7 | U21: =(T21)/(N21+SUMIFS(Table_query[Value $ ex GST],Table_query[Work Type],G21,Table_query[Phase],"5.S - Selected",Table_query[Path],"sites/RGSales/Shared Documents/General/1.Open Opportunities")+SUMIFS(Table_query[Value $ ex GST],Table_query[Work Type],G21,Table_query[Phase],"3.DF - Submitted",Table_query[Path],"sites/RGSales/Shared Documents/General/1.Open Opportunities")+SUMIFS(Table_query[Value $ ex GST],Table_query[Work Type],G21,Table_query[Phase],"3.DF - Submitted",Table_query[Path],"sites/RGSales/Shared Documents/General/1.Open Opportunities")) -> 0.53173149 | Z21: Work Type | AA21: (Multiple Items)
G22: Delivery | H22: =SUMIF(Job_Status[Work Type],G22,Job_Status[To Date Gross Profit]) -> 1971998.7 | I22: =H22/SUMIFS(Job_Status[Actual],Job_Status[Work Type],Summary!G22) -> 0.29816909 | J22: =SUMIF(Job_Status[Work Type],Summary!G22,Job_Status[Actual]) -> 6613692.8 | K22: =IFERROR(H22/J22,"") -> 0.29816909 | L22: =SUMIF(Job_Status[Work Type],G22,Job_Status[GP at completion]) -> 2913123.9 | M22: =L22/SUMIFS(Job_Status[Forecasted Revenue],Job_Status[Work Type],Summary!G22) -> 0.26707216 | N22: =SUMIF(Job_Status[Work Type],G22,Job_Status[Forecasted Revenue]) -> 10907628 | O22: =L22/N22 -> 0.26707216 | P22: =IF(CompanyGoodToggle=TRUE,SUMIFS(TotalGMContribution[FY25/26],TotalGMContribution[Work Type],Summary!$G22,TotalGMContribution[Open Opps Phase],"5.S - Selected",TotalGMContribution[Opps Status],"Good"),0)+IF(CompanyFairToggle=TRUE,SUMIFS(TotalGMContribution[FY25/26],TotalGMContribution[Work Type],Summary!$G22,TotalGMContribution[Open Opps Phase],"5.S - Selected",TotalGMContribution[Opps Status],"Fair"),0)+IF(CompanyRiskToggle=TRUE,SUMIFS(TotalGMContribution[FY25/26],TotalGMContribution[Work Type],Summary!$G22,TotalGMContribution[Open Opps Phase],"5.S - Selected",TotalGMContribution[Opps Status],"Risk"),0)+L22 -> 2913123.9 | Q22: {=(SUMPRODUCT(Table_query[Value $ ex GST]*Table_query[Margin]*(Table_query[Work Type]=G22)*(Table_query[Phase]="5.S - Selected")*(Table_query[Path]="sites/RGSales/Shared Documents/General/1.Open Opportunities"))+L22)/(N22+SUMIFS(Table_query[Value $ ex GST],Table_query[Work Type],G22,Table_query[Phase],"5.S - Selected",Table_query[Path],"sites/RGSales/Shared Documents/General/1.Open Opportunities"))} -> 0.26707216 | R22: =IF(CompanyGoodToggle=TRUE,SUMIFS(TotalGMContribution[FY25/26],TotalGMContribution[Work Type],Summary!$G22,TotalGMContribution[Open Opps Phase],"4.DVF - Shortlisted",TotalGMContribution[Opps Status],"Good"),0)+IF(CompanyFairToggle=TRUE,SUMIFS(TotalGMContribution[FY25/26],TotalGMContribution[Work Type],Summary!$G22,TotalGMContribution[Open Opps Phase],"4.DVF - Shortlisted",TotalGMContribution[Opps Status],"Fair"),0)+IF(CompanyRiskToggle=TRUE,SUMIFS(TotalGMContribution[FY25/26],TotalGMContribution[Work Type],Summary!$G22,TotalGMContribution[Open Opps Phase],"4.DVF - Shortlisted",TotalGMContribution[Opps Status],"Risk"),0)+P22 -> 5088998.3 | S22: =(R22)/(N22+SUMIFS(Table_query[Value $ ex GST],Table_query[Work Type],G22,Table_query[Phase],"5.S - Selected",Table_query[Path],"sites/RGSales/Shared Documents/General/1.Open Opportunities")+SUMIFS(Table_query[Value $ ex GST],Table_query[Work Type],G22,Table_query[Phase],"3.DF - Submitted",Table_query[Path],"sites/RGSales/Shared Documents/General/1.Open Opportunities")) -> 0.39372873 | T22: =IF(CompanyGoodToggle=TRUE,SUMIFS(TotalGMContribution[FY25/26],TotalGMContribution[Work Type],Summary!$G22,TotalGMContribution[Open Opps Phase],"3.DF - Submitted",TotalGMContribution[Opps Status],"Good"),0)+IF(CompanyFairToggle=TRUE,SUMIFS(TotalGMContribution[FY25/26],TotalGMContribution[Work Type],Summary!$G22,TotalGMContribution[Open Opps Phase],"3.DF - Submitted",TotalGMContribution[Opps Status],"Fair"),0)+IF(CompanyRiskToggle=TRUE,SUMIFS(TotalGMContribution[FY25/26],TotalGMContribution[Work Type],Summary!$G22,TotalGMContribution[Open Opps Phase],"3.DF - Submitted",TotalGMContribution[Opps Status],"Risk"),0)+R22 -> 5088998.3 | U22: =(T22)/(N22+SUMIFS(Table_query[Value $ ex GST],Table_query[Work Type],G22,Table_query[Phase],"5.S - Selected",Table_query[Path],"sites/RGSales/Shared Documents/General/1.Open Opportunities")+SUMIFS(Table_query[Value $ ex GST],Table_query[Work Type],G22,Table_query[Phase],"3.DF - Submitted",Table_query[Path],"sites/RGSales/Shared Documents/General/1.Open Opportunities")+SUMIFS(Table_query[Value $ ex GST],Table_query[Work Type],G22,Table_query[Phase],"3.DF - Submitted",Table_query[Path],"sites/RGSales/Shared Documents/General/1.Open Opportunities")) -> 0.3405687
G23: Resource Pool | H23: =SUMIF(Job_Status[Work Type],G23,Job_Status[To Date Gross Profit]) -> 332766.98 | I23: =H23/SUMIFS(Job_Status[Actual],Job_Status[Work Type],Summary!G23) -> 0.23156783 | J23: =SUMIF(Job_Status[Work Type],Summary!G23,Job_Status[Actual]) -> 1437017.3 | K23: =IFERROR(H23/J23,"") -> 0.23156783 | L23: =SUMIF(Job_Status[Work Type],G23,Job_Status[GP at completion]) -> 392169.53 | M23: =L23/SUMIFS(Job_Status[Forecasted Revenue],Job_Status[Work Type],Summary!G23) -> 0.21582186 | N23: =SUMIF(Job_Status[Work Type],G23,Job_Status[Forecasted Revenue]) -> 1817098.3 | O23: =L23/N23 -> 0.21582186 | P23: =IF(CompanyGoodToggle=TRUE,SUMIFS(TotalGMContribution[FY25/26],TotalGMContribution[Work Type],Summary!$G23,TotalGMContribution[Open Opps Phase],"5.S - Selected",TotalGMContribution[Opps Status],"Good"),0)+IF(CompanyFairToggle=TRUE,SUMIFS(TotalGMContribution[FY25/26],TotalGMContribution[Work Type],Summary!$G23,TotalGMContribution[Open Opps Phase],"5.S - Selected",TotalGMContribution[Opps Status],"Fair"),0)+IF(CompanyRiskToggle=TRUE,SUMIFS(TotalGMContribution[FY25/26],TotalGMContribution[Work Type],Summary!$G23,TotalGMContribution[Open Opps Phase],"5.S - Selected",TotalGMContribution[Opps Status],"Risk"),0)+L23 -> 392169.53 | Q23: {=(SUMPRODUCT(Table_query[Value $ ex GST]*Table_query[Margin]*(Table_query[Work Type]=G23)*(Table_query[Phase]="5.S - Selected")*(Table_query[Path]="sites/RGSales/Shared Documents/General/1.Open Opportunities"))+L23)/(N23+SUMIFS(Table_query[Value $ ex GST],Table_query[Work Type],G23,Table_query[Phase],"5.S - Selected",Table_query[Path],"sites/RGSales/Shared Documents/General/1.Open Opportunities"))} -> 0.21582186 | R23: =IF(CompanyGoodToggle=TRUE,SUMIFS(TotalGMContribution[FY25/26],TotalGMContribution[Work Type],Summary!$G23,TotalGMContribution[Open Opps Phase],"4.DVF - Shortlisted",TotalGMContribution[Opps Status],"Good"),0)+IF(CompanyFairToggle=TRUE,SUMIFS(TotalGMContribution[FY25/26],TotalGMContribution[Work Type],Summary!$G23,TotalGMContribution[Open Opps Phase],"4.DVF - Shortlisted",TotalGMContribution[Opps Status],"Fair"),0)+IF(CompanyRiskToggle=TRUE,SUMIFS(TotalGMContribution[FY25/26],TotalGMContribution[Work Type],Summary!$G23,TotalGMContribution[Open Opps Phase],"4.DVF - Shortlisted",TotalGMContribution[Opps Status],"Risk"),0)+P23 -> 392169.53 | S23: =(R23)/(N23+SUMIFS(Table_query[Value $ ex GST],Table_query[Work Type],G23,Table_query[Phase],"5.S - Selected",Table_query[Path],"sites/RGSales/Shared Documents/General/1.Open Opportunities")+SUMIFS(Table_query[Value $ ex GST],Table_query[Work Type],G23,Table_query[Phase],"3.DF - Submitted",Table_query[Path],"sites/RGSales/Shared Documents/General/1.Open Opportunities")) -> 0.17917804 | T23: =IF(CompanyGoodToggle=TRUE,SUMIFS(TotalGMContribution[FY25/26],TotalGMContribution[Work Type],Summary!$G23,TotalGMContribution[Open Opps Phase],"3.DF - Submitted",TotalGMContribution[Opps Status],"Good"),0)+IF(CompanyFairToggle=TRUE,SUMIFS(TotalGMContribution[FY25/26],TotalGMContribution[Work Type],Summary!$G23,TotalGMContribution[Open Opps Phase],"3.DF - Submitted",TotalGMContribution[Opps Status],"Fair"),0)+IF(CompanyRiskToggle=TRUE,SUMIFS(TotalGMContribution[FY25/26],TotalGMContribution[Work Type],Summary!$G23,TotalGMContribution[Open Opps Phase],"3.DF - Submitted",TotalGMContribution[Opps Status],"Risk"),0)+R23 -> 392169.53 | U23: =(T23)/(N23+SUMIFS(Table_query[Value $ ex GST],Table_query[Work Type],G23,Table_query[Phase],"5.S - Selected",Table_query[Path],"sites/RGSales/Shared Documents/General/1.Open Opportunities")+SUMIFS(Table_query[Value $ ex GST],Table_query[Work Type],G23,Table_query[Phase],"3.DF - Submitted",Table_query[Path],"sites/RGSales/Shared Documents/General/1.Open Opportunities")+SUMIFS(Table_query[Value $ ex GST],Table_query[Work Type],G23,Table_query[Phase],"3.DF - Submitted",Table_query[Path],"sites/RGSales/Shared Documents/General/1.Open Opportunities")) -> 0.15317146 | Z23: Phase | AA23: Name | AB23: Status
G24: Labour Hire | H24: =SUMIF(Job_Status[Work Type],G24,Job_Status[To Date Gross Profit]) -> 461799.6 | I24: =H24/SUMIFS(Job_Status[Actual],Job_Status[Work Type],Summary!G24) -> 0.14212595 | J24: =SUMIF(Job_Status[Work Type],Summary!G24,Job_Status[Actual]) -> 3249227.9 | K24: =IFERROR(H24/J24,"") -> 0.14212595 | L24: =SUMIF(Job_Status[Work Type],G24,Job_Status[GP at completion]) -> 706837.4 | M24: =L24/SUMIFS(Job_Status[Forecasted Revenue],Job_Status[Work Type],Summary!G24) -> 0.13378032 | N24: =SUMIF(Job_Status[Work Type],G24,Job_Status[Forecasted Revenue]) -> 5283567.9 | O24: =L24/N24 -> 0.13378032 | P24: =IF(CompanyGoodToggle=TRUE,SUMIFS(TotalGMContribution[FY25/26],TotalGMContribution[Work Type],Summary!$G24,TotalGMContribution[Open Opps Phase],"5.S - Selected",TotalGMContribution[Opps Status],"Good"),0)+IF(CompanyFairToggle=TRUE,SUMIFS(TotalGMContribution[FY25/26],TotalGMContribution[Work Type],Summary!$G24,TotalGMContribution[Open Opps Phase],"5.S - Selected",TotalGMContribution[Opps Status],"Fair"),0)+IF(CompanyRiskToggle=TRUE,SUMIFS(TotalGMContribution[FY25/26],TotalGMContribution[Work Type],Summary!$G24,TotalGMContribution[Open Opps Phase],"5.S - Selected",TotalGMContribution[Opps Status],"Risk"),0)+L24 -> 706837.4 | Q24: {=(SUMPRODUCT(Table_query[Value $ ex GST]*Table_query[Margin]*(Table_query[Work Type]=G24)*(Table_query[Phase]="5.S - Selected")*(Table_query[Path]="sites/RGSales/Shared Documents/General/1.Open Opportunities"))+L24)/(N24+SUMIFS(Table_query[Value $ ex GST],Table_query[Work Type],G24,Table_query[Phase],"5.S - Selected",Table_query[Path],"sites/RGSales/Shared Documents/General/1.Open Opportunities"))} -> 0.13378032 | R24: =IF(CompanyGoodToggle=TRUE,SUMIFS(TotalGMContribution[FY25/26],TotalGMContribution[Work Type],Summary!$G24,TotalGMContribution[Open Opps Phase],"4.DVF - Shortlisted",TotalGMContribution[Opps Status],"Good"),0)+IF(CompanyFairToggle=TRUE,SUMIFS(TotalGMContribution[FY25/26],TotalGMContribution[Work Type],Summary!$G24,TotalGMContribution[Open Opps Phase],"4.DVF - Shortlisted",TotalGMContribution[Opps Status],"Fair"),0)+IF(CompanyRiskToggle=TRUE,SUMIFS(TotalGMContribution[FY25/26],TotalGMContribution[Work Type],Summary!$G24,TotalGMContribution[Open Opps Phase],"4.DVF - Shortlisted",TotalGMContribution[Opps Status],"Risk"),0)+P24 -> 737942.84 | S24: =(R24)/(N24+SUMIFS(Table_query[Value $ ex GST],Table_query[Work Type],G24,Table_query[Phase],"5.S - Selected",Table_query[Path],"sites/RGSales/Shared Documents/General/1.Open Opportunities")+SUMIFS(Table_query[Value $ ex GST],Table_query[Work Type],G24,Table_query[Phase],"3.DF - Submitted",Table_query[Path],"sites/RGSales/Shared Documents/General/1.Open Opportunities")) -> 0.085368475 | T24: =IF(CompanyGoodToggle=TRUE,SUMIFS(TotalGMContribution[FY25/26],TotalGMContribution[Work Type],Summary!$G24,TotalGMContribution[Open Opps Phase],"3.DF - Submitted",TotalGMContribution[Opps Status],"Good"),0)+IF(CompanyFairToggle=TRUE,SUMIFS(TotalGMContribution[FY25/26],TotalGMContribution[Work Type],Summary!$G24,TotalGMContribution[Open Opps Phase],"3.DF - Submitted",TotalGMContribution[Opps Status],"Fair"),0)+IF(CompanyRiskToggle=TRUE,SUMIFS(TotalGMContribution[FY25/26],TotalGMContribution[Work Type],Summary!$G24,TotalGMContribution[Open Opps Phase],"3.DF - Submitted",TotalGMContribution[Opps Status],"Risk"),0)+R24 -> 737942.84 | U24: =(T24)/(N24+SUMIFS(Table_query[Value $ ex GST],Table_query[Work Type],G24,Table_query[Phase],"5.S - Selected",Table_query[Path],"sites/RGSales/Shared Documents/General/1.Open Opportunities")+SUMIFS(Table_query[Value $ ex GST],Table_query[Work Type],G24,Table_query[Phase],"3.DF - Submitted",Table_query[Path],"sites/RGSales/Shared Documents/General/1.Open Opportunities")+SUMIFS(Table_query[Value $ ex GST],Table_query[Work Type],G24,Table_query[Phase],"3.DF - Submitted",Table_query[Path],"sites/RGSales/Shared Documents/General/1.Open Opportunities")) -> 0.061470403 | Z24: 4.DVF - Shortlisted | AA24: DPSXXX RFQ Cyber Security Assessor 202601 | AB24: Risk
G25: TOTAL | H25: =SUM(H21:H24) -> 4318737 | I25: =Job_Status[[#Totals],[TD GM(%)]] -> 0.30556877 | L25: =SUM(L21:L24) -> 5467112.5 | M25: =Job_Status[[#Totals],[Forecast GM @ completion (%)]] -> 0.26354384 | P25: =SUM(P21:P24) -> 5467112.5 | Q25: =P25/P7 -> 0.26354384 | R25: =SUM(R21:R24) -> 7674092.4 | S25: =R25/R7 -> 0.30401651 | T25: =SUM(T21:T24) -> 7674092.4 | U25: =T25/T7 -> 0.30401651 | AA25: FWO001-XX Digital Transformation CPBC - PoC | AB25: Risk
AA26: FWO001-XX Digital Transformation CPBC - Revision and Submission Support | AB26: Fair
C27: REVENUE | D27: Q1 | E27: Q2 | F27: Q3 | G27: Q4 | H27: FY25-26 | AA27: LAB001-01 DCC Program Plan (Extension) | AB27: Good
C28: Good' Target | D28: =SUM('COMPANY Spread'!Q60:S60) -> 7611688.3 | E28: =SUM('COMPANY Spread'!T60:V60) -> 7187445.9 | F28: =SUM('COMPANY Spread'!W60:Y60) -> 9573809.5 | G28: =SUM('COMPANY Spread'!Z60:AB60) -> 9573809.5 | H28: =SUM(D28:G28) -> 33946753 | AA28: SAU045-XX Senior Technology Architect (Sidd) | AB28: Good
C29: YTD | D29: =SUM(Job_Status[[#Totals],[Revenue Q1]]) -> 5912887.3 | E29: =SUM(Job_Status[[#Totals],[Revenue Q2]]) -> 6505901.8 | F29: =SUM(Job_Status[[#Totals],[Revenue Q3]]) -> 1714647.9 | G29: =SUM(Job_Status[[#Totals],[Revenue Q4]]) -> 0 | H29: =SUM(D29:G29) -> 14133437 | AA29: SAU046-XX Delivery Manager (Alex) | AB29: Good
C30: Forecast | D30: =SUM('COMPANY Spread'!Q54:S54) -> 5912887.3 | E30: =SUM('COMPANY Spread'!T54:V54) -> 6505901.8 | F30: =SUM('COMPANY Spread'!W54:Y54) -> 4737991.5 | G30: =SUM('COMPANY Spread'!Z54:AB54) -> 3473100.6 | H30: =SUM(D30:G30) -> 20629881 | L30: ="$"&ROUNDDOWN(H30-L7,0)&" difference to L7 due to potential write-ups/write-off not broken down by quarters into the future." -> $-114722 difference to L7 due to potential write-ups/write-off not broken down by quarters into the future. | AA30: SAU052-XX Senior Solution Architect (Aniket) | AB30: Good
C31: Variance | D31: =D30-D28 -> -1698801 | E31: =E30-E28 -> -681544.04 | F31: =F30-F28 -> -4835818 | G31: =G30-G28 -> -6100708.9 | H31: =SUM(D31:G31) -> -13316872 | AA31: TECXXX DEWR DE RFQ ERP 202510 | AB31: Good
C32: GM CONT. | D32: Q1 | E32: Q2 | F32: Q3 | G32: Q4 | H32: FY25-26 | AA32: TECXXX INF RFQ TechOne - ERP Products, Implementation, Operational | AB32: Good
C33: Good' Target | D33: =SUM('COMPANY Spread'!C60:E60) -> 2270000 | E33: =SUM('COMPANY Spread'!F60:H60) -> 2320000 | F33: =SUM('COMPANY Spread'!I60:K60) -> 2770000 | G33: =SUM('COMPANY Spread'!L60:N60) -> 2770000 | H33: =SUM(D33:G33) -> 10130000 | AA33: VICXXX DEECA RFQ Permissions System 202512 | AB33: Good
C34: YTD | D34: =Job_Status[[#Totals],[Gross Profit Q1]] -> 1791429.4 | E34: =Job_Status[[#Totals],[Gross Profit Q2]] -> 2131155.7 | F34: =Job_Status[[#Totals],[Gross Profit Q3]] -> 396151.9 | G34: =Job_Status[[#Totals],[Gross Profit Q4]] -> 0 | H34: =SUM(D34:G34) -> 4318737 | Z34: 3.DF - Submitted | AA34: AFPXXX LH-05147 One (1) Lead Business Architect 202512 | AB34: Risk
C35: Forecast | D35: =SUM('COMPANY Spread'!C54:E54) -> 1791429.4 | E35: =SUM('COMPANY Spread'!F54:H54) -> 2131155.7 | F35: =SUM('COMPANY Spread'!I54:K54) -> 901231.5 | G35: =SUM('COMPANY Spread'!L54:N54) -> 528573.68 | H35: =SUM(D35:G35) -> 5352390.3 | L35: ="$"&ROUNDDOWN(H35-L16,0)&" difference to L7 due to potential write-ups not broken down by quarters into future." -> $-114722 difference to L7 due to potential write-ups not broken down by quarters into future. | AA35: AGDXXX RFQ Review of ICT Services for AGS 202512 | AB35: Risk
C36: Variance | D36: =D35-D33 -> -478570.6 | E36: =E35-E33 -> -188844.29 | F36: =F35-F33 -> -1868768.5 | G36: =G35-G33 -> -2241426.3 | H36: =SUM(D36:G36) -> -4777609.7 | AA36: AREXXX RFQ Design Future Data Platform 202601 | AB36: Risk
AA37: DAFXXX RFQ Incident and Major Incident Management Review | AB37: Good
AA38: DAFXXX TRACE ServiceNow | AB38: Risk
B39: Opportunity Tracker | AA39: DHAXXX LH-04367 Two Senior Pega Analyst 202508 | AB39: Risk
B40: Opportunity Status | C40: A | D40: Q | E40: DF | F40: DVF | G40: S | AA40: DHAXXX LH-04634 One Senior Pega Developer 202509 | AB40: Risk
B41: Good | C41: =IF(VATSelector="ALL",COUNTIFS(Table_query[Path],"sites/RGSales/Shared Documents/General/1.Open Opportunities",Table_query[Phase],_xlfn.XLOOKUP(C$40,Phase[Phase Code],Phase[Phase Description]),Table_query[Status],Summary!$B41),COUNTIFS(Table_query[Path],"sites/RGSales/Shared Documents/General/1.Open Opportunities",Table_query[Phase],_xlfn.XLOOKUP(C$40,Phase[Phase Code],Phase[Phase Description]),Table_query[Status],Summary!$B41,Table_query[VAT],VATSelector)) -> 2 | D41: =IF(VATSelector="ALL",COUNTIFS(Table_query[Path],"sites/RGSales/Shared Documents/General/1.Open Opportunities",Table_query[Phase],_xlfn.XLOOKUP(D$40,Phase[Phase Code],Phase[Phase Description]),Table_query[Status],Summary!$B41),COUNTIFS(Table_query[Path],"sites/RGSales/Shared Documents/General/1.Open Opportunities",Table_query[Phase],_xlfn.XLOOKUP(D$40,Phase[Phase Code],Phase[Phase Description]),Table_query[Status],Summary!$B41,Table_query[VAT],VATSelector)) -> 7 | E41: 1 | F41: =IF(VATSelector="ALL",COUNTIFS(Table_query[Path],"sites/RGSales/Shared Documents/General/1.Open Opportunities",Table_query[Phase],_xlfn.XLOOKUP(F$40,Phase[Phase Code],Phase[Phase Description]),Table_query[Status],Summary!$B41),COUNTIFS(Table_query[Path],"sites/RGSales/Shared Documents/General/1.Open Opportunities",Table_query[Phase],_xlfn.XLOOKUP(F$40,Phase[Phase Code],Phase[Phase Description]),Table_query[Status],Summary!$B41,Table_query[VAT],VATSelector)) -> 9 | G41: =IF(VATSelector="ALL",COUNTIFS(Table_query[Path],"sites/RGSales/Shared Documents/General/1.Open Opportunities",Table_query[Phase],_xlfn.XLOOKUP(G$40,Phase[Phase Code],Phase[Phase Description]),Table_query[Status],Summary!$B41),COUNTIFS(Table_query[Path],"sites/RGSales/Shared Documents/General/1.Open Opportunities",Table_query[Phase],_xlfn.XLOOKUP(G$40,Phase[Phase Code],Phase[Phase Description]),Table_query[Status],Summary!$B41,Table_query[VAT],VATSelector)) -> 0 | AA41: DHAXXX RFQ On-demand services for mainframe Capability 202511 | AB41: Risk
B42: Fair | C42: =IF(VATSelector="ALL",COUNTIFS(Table_query[Path],"sites/RGSales/Shared Documents/General/1.Open Opportunities",Table_query[Phase],_xlfn.XLOOKUP(C$40,Phase[Phase Code],Phase[Phase Description]),Table_query[Status],Summary!$B42),COUNTIFS(Table_query[Path],"sites/RGSales/Shared Documents/General/1.Open Opportunities",Table_query[Phase],_xlfn.XLOOKUP(C$40,Phase[Phase Code],Phase[Phase Description]),Table_query[Status],Summary!$B42,Table_query[VAT],VATSelector)) -> 16 | D42: =IF(VATSelector="ALL",COUNTIFS(Table_query[Path],"sites/RGSales/Shared Documents/General/1.Open Opportunities",Table_query[Phase],_xlfn.XLOOKUP(D$40,Phase[Phase Code],Phase[Phase Description]),Table_query[Status],Summary!$B42),COUNTIFS(Table_query[Path],"sites/RGSales/Shared Documents/General/1.Open Opportunities",Table_query[Phase],_xlfn.XLOOKUP(D$40,Phase[Phase Code],Phase[Phase Description]),Table_query[Status],Summary!$B42,Table_query[VAT],VATSelector)) -> 2 | E42: =IF(VATSelector="ALL",COUNTIFS(Table_query[Path],"sites/RGSales/Shared Documents/General/1.Open Opportunities",Table_query[Phase],_xlfn.XLOOKUP(E$40,Phase[Phase Code],Phase[Phase Description]),Table_query[Status],Summary!$B42),COUNTIFS(Table_query[Path],"sites/RGSales/Shared Documents/General/1.Open Opportunities",Table_query[Phase],_xlfn.XLOOKUP(E$40,Phase[Phase Code],Phase[Phase Description]),Table_query[Status],Summary!$B42,Table_query[VAT],VATSelector)) -> 1 | F42: =IF(VATSelector="ALL",COUNTIFS(Table_query[Path],"sites/RGSales/Shared Documents/General/1.Open Opportunities",Table_query[Phase],_xlfn.XLOOKUP(F$40,Phase[Phase Code],Phase[Phase Description]),Table_query[Status],Summary!$B42),COUNTIFS(Table_query[Path],"sites/RGSales/Shared Documents/General/1.Open Opportunities",Table_query[Phase],_xlfn.XLOOKUP(F$40,Phase[Phase Code],Phase[Phase Description]),Table_query[Status],Summary!$B42,Table_query[VAT],VATSelector)) -> 1 | G42: =IF(VATSelector="ALL",COUNTIFS(Table_query[Path],"sites/RGSales/Shared Documents/General/1.Open Opportunities",Table_query[Phase],_xlfn.XLOOKUP(G$40,Phase[Phase Code],Phase[Phase Description]),Table_query[Status],Summary!$B42),COUNTIFS(Table_query[Path],"sites/RGSales/Shared Documents/General/1.Open Opportunities",Table_query[Phase],_xlfn.XLOOKUP(G$40,Phase[Phase Code],Phase[Phase Description]),Table_query[Status],Summary!$B42,Table_query[VAT],VATSelector)) -> 0 | AA42: DODXXX RFQ Workforce Prioritisation Workshops 202512 | AB42: Risk
B43: Risk | C43: =IF(VATSelector="ALL",COUNTIFS(Table_query[Path],"sites/RGSales/Shared Documents/General/1.Open Opportunities",Table_query[Phase],_xlfn.XLOOKUP(C$40,Phase[Phase Code],Phase[Phase Description]),Table_query[Status],Summary!$B43),COUNTIFS(Table_query[Path],"sites/RGSales/Shared Documents/General/1.Open Opportunities",Table_query[Phase],_xlfn.XLOOKUP(C$40,Phase[Phase Code],Phase[Phase Description]),Table_query[Status],Summary!$B43,Table_query[VAT],VATSelector)) -> 3 | D43: =IF(VATSelector="ALL",COUNTIFS(Table_query[Path],"sites/RGSales/Shared Documents/General/1.Open Opportunities",Table_query[Phase],_xlfn.XLOOKUP(D$40,Phase[Phase Code],Phase[Phase Description]),Table_query[Status],Summary!$B43),COUNTIFS(Table_query[Path],"sites/RGSales/Shared Documents/General/1.Open Opportunities",Table_query[Phase],_xlfn.XLOOKUP(D$40,Phase[Phase Code],Phase[Phase Description]),Table_query[Status],Summary!$B43,Table_query[VAT],VATSelector)) -> 1 | E43: =IF(VATSelector="ALL",COUNTIFS(Table_query[Path],"sites/RGSales/Shared Documents/General/1.Open Opportunities",Table_query[Phase],_xlfn.XLOOKUP(E$40,Phase[Phase Code],Phase[Phase Description]),Table_query[Status],Summary!$B43),COUNTIFS(Table_query[Path],"sites/RGSales/Shared Documents/General/1.Open Opportunities",Table_query[Phase],_xlfn.XLOOKUP(E$40,Phase[Phase Code],Phase[Phase Description]),Table_query[Status],Summary!$B43,Table_query[VAT],VATSelector)) -> 9 | F43: =IF(VATSelector="ALL",COUNTIFS(Table_query[Path],"sites/RGSales/Shared Documents/General/1.Open Opportunities",Table_query[Phase],_xlfn.XLOOKUP(F$40,Phase[Phase Code],Phase[Phase Description]),Table_query[Status],Summary!$B43),COUNTIFS(Table_query[Path],"sites/RGSales/Shared Documents/General/1.Open Opportunities",Table_query[Phase],_xlfn.XLOOKUP(F$40,Phase[Phase Code],Phase[Phase Description]),Table_query[Status],Summary!$B43,Table_query[VAT],VATSelector)) -> 2 | G43: =IF(VATSelector="ALL",COUNTIFS(Table_query[Path],"sites/RGSales/Shared Documents/General/1.Open Opportunities",Table_query[Phase],_xlfn.XLOOKUP(G$40,Phase[Phase Code],Phase[Phase Description]),Table_query[Status],Summary!$B43),COUNTIFS(Table_query[Path],"sites/RGSales/Shared Documents/General/1.Open Opportunities",Table_query[Phase],_xlfn.XLOOKUP(G$40,Phase[Phase Code],Phase[Phase Description]),Table_query[Status],Summary!$B43,Table_query[VAT],VATSelector)) -> 0 | AA43: SAUXXX SPES Micro-Panel - RFQLH-02700 EL1 Senior Software Engineer | AB43: Risk
AA44: VICXXX CenITex Initial Strategy for One VPS | AB44: Good
...

Sheet COMPANY Spread
B41: Cumulative View - Gross Margin Contribution | P41: Cumulative View - Revenue
B42: STATUS | C42: July | D42: August | E42: September | F42: October | G42: November | H42: December | I42: January | J42: February | K42: March | L42: April | M42: May | N42: June | P42: STATUS | Q42: July | R42: August | S42: September | T42: October | U42: November | V42: December | W42: January | X42: February | Y42: March | Z42: April | AA42: May | AB42: June
B43: C | C43: =C54 -> 371824.25 | D43: =SUM($C54:D54) -> 996334.71 | E43: =SUM($C54:E54) -> 1791429.4 | F43: =SUM($C54:F54) -> 2809151.2 | G43: =SUM($C54:G54) -> 3458448.8 | H43: =SUM($C54:H54) -> 3922585.1 | I43: =SUM($C54:I54) -> 4250178.2 | J43: =SUM($C54:J54) -> 4545961.7 | K43: =SUM($C54:K54) -> 4823816.6 | ... N43: =SUM($C54:N54) -> 5352390.3 | P43: C | Q43: =Q54 -> 1489443.4 | R43: =SUM($Q54:R54) -> 3380720.4 | S43: =SUM($Q54:S54) -> 5912887.3 | T43: =SUM($Q54:T54) -> 8541298.4 | U43: =SUM($Q54:U54) -> 10744629 | V43: =SUM($Q54:V54) -> 12418789 | W43: =SUM($Q54:W54) -> 13865663 | X43: =SUM($Q54:X54) -> 15392756 | Y43: =SUM($Q54:Y54) -> 17156781 | ... AB43: =SUM($Q54:AB54) -> 20629881
B44: S | C44: =C43+C55 -> 371824.25 | D44: =SUM($C55:D55)+D43 -> 996334.71 | E44: =SUM($C55:E55)+E43 -> 1791429.4 | F44: =SUM($C55:F55)+F43 -> 2809151.2 | G44: =SUM($C55:G55)+G43 -> 3458448.8 | H44: =SUM($C55:H55)+H43 -> 3922585.1 | I44: =SUM($C55:I55)+I43 -> 4250178.2 | J44: =SUM($C55:J55)+J43 -> 4545961.7 | K44: =SUM($C55:K55)+K43 -> 4823816.6 | ... N44: =SUM($C55:N55)+N43 -> 5352390.3 | P44: S | Q44: =Q55+Q43 -> 1489443.4 | R44: =SUM($Q55:R55)+R43 -> 3380720.4 | S44: =SUM($Q55:S55)+S43 -> 5912887.3 | T44: =SUM($Q55:T55)+T43 -> 8541298.4 | U44: =SUM($Q55:U55)+U43 -> 10744629 | V44: =SUM($Q55:V55)+V43 -> 12418789 | W44: =SUM($Q55:W55)+W43 -> 13865663 | X44: =SUM($Q55:X55)+X43 -> 15392756 | Y44: =SUM($Q55:Y55)+Y43 -> 17156781 | ... AB44: =SUM($Q55:AB55)+AB43 -> 20629881
B45: DVF | C45: =C44+C56 -> 371824.25 | D45: =SUM($C56:D56)+D44 -> 996334.71 | E45: =SUM($C56:E56)+E44 -> 1791429.4 | F45: =SUM($C56:F56)+F44 -> 2809151.2 | G45: =SUM($C56:G56)+G44 -> 3458448.8 | H45: =SUM($C56:H56)+H44 -> 3922585.1 | I45: =SUM($C56:I56)+I44 -> 4250178.2 | J45: =SUM($C56:J56)+J44 -> 4554962.1 | K45: =SUM($C56:K56)+K44 -> 4878192.1 | ... N45: =SUM($C56:N56)+N44 -> 7559370.1 | P45: DVF | Q45: =Q56+Q44 -> 1489443.4 | R45: =SUM($Q56:R56)+R44 -> 3380720.4 | S45: =SUM($Q56:S56)+S44 -> 5912887.3 | T45: =SUM($Q56:T56)+T44 -> 8541298.4 | U45: =SUM($Q56:U56)+U44 -> 10744629 | V45: =SUM($Q56:V56)+V44 -> 12418789 | W45: =SUM($Q56:W56)+W44 -> 13865663 | X45: =SUM($Q56:X56)+X44 -> 15412800 | Y45: =SUM($Q56:Y56)+Y44 -> 17285041 | ... AB45: =SUM($Q56:AB56)+AB44 -> 25127632
B46: DF+ | C46: =C45+C57 -> 371824.25 | D46: =SUM($C57:D57)+D45 -> 996334.71 | E46: =SUM($C57:E57)+E45 -> 1791429.4 | F46: =SUM($C57:F57)+F45 -> 2809151.2 | G46: =SUM($C57:G57)+G45 -> 3458448.8 | H46: =SUM($C57:H57)+H45 -> 3922585.1 | I46: =SUM($C57:I57)+I45 -> 4250178.2 | J46: =SUM($C57:J57)+J45 -> 4554962.1 | K46: =SUM($C57:K57)+K45 -> 4878192.1 | ... N46: =SUM($C57:N57)+N45 -> 7559370.1 | P46: DF+ | Q46: =Q57+Q45 -> 1489443.4 | R46: =SUM($Q57:R57)+R45 -> 3380720.4 | S46: =SUM($Q57:S57)+S45 -> 5912887.3 | T46: =SUM($Q57:T57)+T45 -> 8541298.4 | U46: =SUM($Q57:U57)+U45 -> 10744629 | V46: =SUM($Q57:V57)+V45 -> 12418789 | W46: =SUM($Q57:W57)+W45 -> 13865663 | X46: =SUM($Q57:X57)+X45 -> 15412800 | Y46: =SUM($Q57:Y57)+Y45 -> 17285041 | ... AB46: =SUM($Q57:AB57)+AB45 -> 25127632
B47: Q+ | C47: =C46+C58 -> 371824.25 | D47: =SUM($C58:D58)+D46 -> 996334.71 | E47: =SUM($C58:E58)+E46 -> 1791429.4 | F47: =SUM($C58:F58)+F46 -> 2809151.2 | G47: =SUM($C58:G58)+G46 -> 3458448.8 | H47: =SUM($C58:H58)+H46 -> 3922585.1 | I47: =SUM($C58:I58)+I46 -> 4250178.2 | J47: =SUM($C58:J58)+J46 -> 4554962.1 | K47: =SUM($C58:K58)+K46 -> 4878192.1 | ... N47: =SUM($C58:N58)+N46 -> 7559370.1 | P47: Q+ | Q47: =Q58+Q46 -> 1489443.4 | R47: =SUM($Q58:R58)+R46 -> 3380720.4 | S47: =SUM($Q58:S58)+S46 -> 5912887.3 | T47: =SUM($Q58:T58)+T46 -> 8541298.4 | U47: =SUM($Q58:U58)+U46 -> 10744629 | V47: =SUM($Q58:V58)+V46 -> 12418789 | W47: =SUM($Q58:W58)+W46 -> 13865663 | X47: =SUM($Q58:X58)+X46 -> 15532800 | Y47: =SUM($Q58:Y58)+Y46 -> 17525041 | ... AB47: =SUM($Q58:AB58)+AB46 -> 26063346
B48: GREAT | C48: =C59 -> 971166.67 | D48: =SUM($C59:D59) -> 1946833.3 | E48: =SUM($C59:E59) -> 2937500 | F48: =SUM($C59:F59) -> 3891666.7 | G48: =SUM($C59:G59) -> 4845833.3 | H48: =SUM($C59:H59) -> 5800000 | I48: =SUM($C59:I59) -> 7016666.7 | J48: =SUM($C59:J59) -> 8233333.3 | K48: =SUM($C59:K59) -> 9450000 | ... N48: =SUM($C59:N59) -> 13100000 | P48: GREAT | Q48: =Q59 -> 3179953.1 | R48: =SUM($Q59:R59) -> 6374906.2 | S48: =SUM($Q59:S59) -> 9619859.3 | T48: =SUM($Q59:T59) -> 12432540 | U48: =SUM($Q59:U59) -> 15245220 | V48: =SUM($Q59:V59) -> 18057900 | W48: =SUM($Q59:W59) -> 22211490 | X48: =SUM($Q59:X59) -> 26365079 | Y48: =SUM($Q59:Y59) -> 30518669 | ... AB48: =SUM($Q59:AB59) -> 42979437
B49: GOOD | C49: =C60 -> 748666.67 | D49: =SUM($C60:D60) -> 1501833.3 | E49: =SUM($C60:E60) -> 2270000 | F49: =SUM($C60:F60) -> 3043333.3 | G49: =SUM($C60:G60) -> 3816666.7 | H49: =SUM($C60:H60) -> 4590000 | I49: =SUM($C60:I60) -> 5513333.3 | J49: =SUM($C60:J60) -> 6436666.7 | K49: =SUM($C60:K60) -> 7360000 | ... N49: =SUM($C60:N60) -> 10130000 | P49: GOOD | Q49: =Q60 -> 2510562.8 | R49: =SUM($Q60:R60) -> 5036125.5 | S49: =SUM($Q60:S60) -> 7611688.3 | T49: =SUM($Q60:T60) -> 10007504 | U49: =SUM($Q60:U60) -> 12403319 | V49: =SUM($Q60:V60) -> 14799134 | W49: =SUM($Q60:W60) -> 17990404 | X49: =SUM($Q60:X60) -> 21181674 | Y49: =SUM($Q60:Y60) -> 24372944 | ... AB49: =SUM($Q60:AB60) -> 33946753
B50: OK | C50: =C61 -> 537000 | D50: =SUM($C61:D61) -> 1078500 | E50: =SUM($C61:E61) -> 1635000 | F50: =SUM($C61:F61) -> 2215000 | G50: =SUM($C61:G61) -> 2795000 | H50: =SUM($C61:H61) -> 3375000 | I50: =SUM($C61:I61) -> 3992500 | J50: =SUM($C61:J61) -> 4610000 | K50: =SUM($C61:K61) -> 5227500 | ... N50: =SUM($C61:N61) -> 7080000 | P50: OK | Q50: =Q61 -> 1877366.9 | R50: =SUM($Q61:R61) -> 3769733.7 | S50: =SUM($Q61:S61) -> 5712100.6 | T50: =SUM($Q61:T61) -> 7643720.3 | U50: =SUM($Q61:U61) -> 9575340.1 | V50: =SUM($Q61:V61) -> 11506960 | W50: =SUM($Q61:W61) -> 13697200 | X50: =SUM($Q61:X61) -> 15887441 | Y50: =SUM($Q61:Y61) -> 18077681 | ... AB50: =SUM($Q61:AB61) -> 24648402
B52: Monthly View - Gross Margin Contribution | P52: Monthly View - Revenue
B53: STATUS | C53: July | D53: August | E53: September | F53: October | G53: November | H53: December | I53: January | J53: February | K53: March | L53: April | M53: May | N53: June | P53: STATUS | Q53: July | R53: August | S53: September | T53: October | U53: November | V53: December | W53: January | X53: February | Y53: March | Z53: April | AA53: May | AB53: June
B54: C | C54: =IF(VATSelector="ALL",Job_Status[[#Totals],[P1]],SUMIF(Job_Status[VAT],VATSelector,Job_Status[P1])) -> 371824.25 | D54: =IF(VATSelector="ALL",Job_Status[[#Totals],[P2]],SUMIF(Job_Status[VAT],VATSelector,Job_Status[P2])) -> 624510.46 | E54: =IF(VATSelector="ALL",Job_Status[[#Totals],[P3]],SUMIF(Job_Status[VAT],VATSelector,Job_Status[P3])) -> 795094.69 | F54: =IF(VATSelector="ALL",Job_Status[[#Totals],[P4]],SUMIF(Job_Status[VAT],VATSelector,Job_Status[P4])) -> 1017721.8 | G54: =IF(VATSelector="ALL",Job_Status[[#Totals],[P5]],SUMIF(Job_Status[VAT],VATSelector,Job_Status[P5])) -> 649297.64 | H54: =IF(VATSelector="ALL",Job_Status[[#Totals],[P6]],SUMIF(Job_Status[VAT],VATSelector,Job_Status[P6])) -> 464136.3 | I54: =IF(VATSelector="ALL",Job_Status[[#Totals],[P7]],SUMIF(Job_Status[VAT],VATSelector,Job_Status[P7])) -> 327593.11 | J54: =IF(VATSelector="ALL",Job_Status[[#Totals],[P8]],SUMIF(Job_Status[VAT],VATSelector,Job_Status[P8])) -> 295783.44 | K54: =IF(VATSelector="ALL",Job_Status[[#Totals],[P9]],SUMIF(Job_Status[VAT],VATSelector,Job_Status[P9])) -> 277854.96 | L54: =IF(VATSelector="ALL",Job_Status[[#Totals],[P10]],SUMIF(Job_Status[VAT],VATSelector,Job_Status[P10])) -> 157710.36 | M54: =IF(VATSelector="ALL",Job_Status[[#Totals],[P11]],SUMIF(Job_Status[VAT],VATSelector,Job_Status[P11])) -> 163082.2 | N54: =IF(VATSelector="ALL",Job_Status[[#Totals],[P12]],SUMIF(Job_Status[VAT],VATSelector,Job_Status[P12])) -> 207781.13 | P54: C | Q54: =Job_Status[[#Totals],[R1]] -> 1489443.4 | R54: =Job_Status[[#Totals],[R2]] -> 1891277 | S54: =Job_Status[[#Totals],[R3]] -> 2532166.9 | T54: =Job_Status[[#Totals],[R4]] -> 2628411.1 | U54: =Job_Status[[#Totals],[R5]] -> 2203330.7 | V54: =Job_Status[[#Totals],[R6]] -> 1674160.1 | W54: =Job_Status[[#Totals],[R7]] -> 1446873.6 | X54: =Job_Status[[#Totals],[R8]] -> 1527093.3 | Y54: =Job_Status[[#Totals],[R9]] -> 1764024.6 | Z54: =Job_Status[[#Totals],[R10]] -> 1139120.8 | AA54: =Job_Status[[#Totals],[R11]] -> 1132235.1 | AB54: =Job_Status[[#Totals],[R12]] -> 1201744.8
